Workbook

Sheet MAIN
A1: CCMS Third party report
B3: Total outstanding | F3: LAA Debt | J3: Third Party Debt
A4: Debt Type | B4: Total | C4: Principal Debt | D4: Interest (late charges) | F4: Total | G4: Principal Debt | H4: Interest (late charges) | J4: Total | K4: Principal Debt | L4: Interest (late charges)
A5: Contributions | B5: =SUM(C5:D5) -> #REF! | C5: =SUM([1]CCMS_CASE_TOTALS_TRUE!GF:GF) -> #REF! | D5: =H5 -> #REF! | F5: =SUM(G5:H5) -> #REF! | G5: =SUM([1]CCMS_CASE_TOTALS_TRUE!GK:GK) -> #REF! | H5: =SUM([1]CCMS_CASE_TOTALS_TRUE!GW:GW) -> #REF! | J5: =B5-F5 -> #REF! | K5: =C5-G5 -> #REF! | L5: =D5-H5 -> #REF!
A6: Costs | B6: =SUM(C6:D6) -> #REF! | C6: =SUM([1]CCMS_CASE_TOTALS_TRUE!GG:GG) -> #REF! | D6: =H6 -> #REF! | F6: =SUM(G6:H6) -> #REF! | G6: =SUM([1]CCMS_CASE_TOTALS_TRUE!GL:GL) -> #REF! | H6: =SUM([1]CCMS_CASE_TOTALS_TRUE!GX:GX) -> #REF! | J6: =B6-F6 -> #REF! | K6: =C6-G6 -> #REF! | L6: =D6-H6 -> #REF!
A7: Damages | B7: =SUM(C7:D7) -> #REF! | C7: =SUM([1]CCMS_CASE_TOTALS_TRUE!GH:GH) -> #REF! | D7: =H7 -> #REF! | F7: =SUM(G7:H7) -> #REF! | G7: =SUM([1]CCMS_CASE_TOTALS_TRUE!GM:GM) -> #REF! | H7: =SUM([1]CCMS_CASE_TOTALS_TRUE!GY:GY) -> #REF! | J7: =B7-F7 -> #REF! | K7: =C7-G7 -> #REF! | L7: =D7-H7 -> #REF!
A8: Revocation | B8: =SUM(C8:D8) -> #REF! | C8: =SUM([1]CCMS_CASE_TOTALS_TRUE!GI:GI) -> #REF! | D8: =H8 -> #REF! | F8: =SUM(G8:H8) -> #REF! | G8: =SUM([1]CCMS_CASE_TOTALS_TRUE!GN:GN) -> #REF! | H8: =SUM([1]CCMS_CASE_TOTALS_TRUE!GZ:GZ) -> #REF! | J8: =B8-F8 -> #REF! | K8: =C8-G8 -> #REF! | L8: =D8-H8 -> #REF!
A9: Statutory Charge - Interest Bearing | B9: =SUM(C9:D9) -> #VALUE! | C9: =SUMIF([1]CCMS_CASE_TOTALS_TRUE!HA:HA,"<>0",[1]CCMS_CASE_TOTALS_TRUE!GJ:GJ) -> #VALUE! | D9: =H9 -> #REF! | F9: =SUM(G9:H9) -> #VALUE! | G9: =SUMIF([1]CCMS_CASE_TOTALS_TRUE!HA:HA,"<>0",[1]CCMS_CASE_TOTALS_TRUE!GO:GO) -> #VALUE! | H9: =SUM([1]CCMS_CASE_TOTALS_TRUE!HA:HA) -> #REF! | J9: =B9-F9 -> #VALUE! | K9: =C9-G9 -> #VALUE! | L9: =D9-H9 -> #REF!
A10: Statutory Charge - Secured | B10: =SUM(C10:D10) -> #VALUE! | C10: =SUMIFS([1]CCMS_CASE_TOTALS_TRUE!GJ:GJ,[1]CCMS_CASE_TOTALS_TRUE!HA:HA,"=0",[1]CCMS_CASE_TOTALS_TRUE!Q:Q,"Y") -> #VALUE! | D10: =H10 -> 0 | F10: =SUM(G10:H10) -> #VALUE! | G10: =SUMIFS([1]CCMS_CASE_TOTALS_TRUE!GO:GO,[1]CCMS_CASE_TOTALS_TRUE!HA:HA,"=0",[1]CCMS_CASE_TOTALS_TRUE!Q:Q,"Y") -> #VALUE! | H10: 0 | J10: =B10-F10 -> #VALUE! | K10: =C10-G10 -> #VALUE! | L10: =D10-H10 -> 0
A11: Statutory Charge - Unsecured | B11: =SUM(C11:D11) -> #VALUE! | C11: =SUMIFS([1]CCMS_CASE_TOTALS_TRUE!GJ:GJ,[1]CCMS_CASE_TOTALS_TRUE!HA:HA,"=0",[1]CCMS_CASE_TOTALS_TRUE!Q:Q,"N") -> #VALUE! | D11: =H11 -> 0 | F11: =SUM(G11:H11) -> #VALUE! | G11: =SUMIFS([1]CCMS_CASE_TOTALS_TRUE!GO:GO,[1]CCMS_CASE_TOTALS_TRUE!HA:HA,"=0",[1]CCMS_CASE_TOTALS_TRUE!Q:Q,"N") -> #VALUE! | H11: 0 | J11: =B11-F11 -> #VALUE! | K11: =C11-G11 -> #VALUE! | L11: =D11-H11 -> 0
A14: Total | B14: =SUM(B5:B13) -> #REF! | C14: =SUM(C5:C13) -> #REF! | D14: =SUM(D5:D13) -> #REF! | F14: =SUM(F5:F13) -> #REF! | G14: =SUM(G5:G13) -> #REF! | H14: =SUM(H5:H13) -> #REF! | J14: =SUM(J5:J13) -> #REF! | K14: =SUM(K5:K13) -> #REF! | L14: =SUM(L5:L13) -> #REF!
F16: CHECKSUM | G16: =#REF!-G14 -> #REF! | H16: =#REF!-H14 -> #REF! | K16: =#REF!-K14 -> #REF! | L16: =0-L14 -> #REF!
F17: CHECKSUM M P | G17: ='Civil Movement Report'!I14+'Civil Movement Report'!I28-'All Debts by Type Summary'!Q17 -> #REF!
F18: CHECKSUM M C | G18: ='Civil Movement Report'!I42+'Civil Movement Report'!I54-'All Debts by Type Summary'!Q19 -> #REF!
A19: Debt Type | B19: Volume
A20: Contributions | B20: =COUNTIF([1]CCMS_CASE_TOTALS_TRUE!GK:GK,">0") -> #VALUE!
A21: Costs | B21: =COUNTIF([1]CCMS_CASE_TOTALS_TRUE!GL:GL,">0") -> #VALUE!
A22: Damages | B22: =COUNTIF([1]CCMS_CASE_TOTALS_TRUE!GM:GM,">0") -> #VALUE!
A23: Revocation | B23: =COUNTIF([1]CCMS_CASE_TOTALS_TRUE!GN:GN,">0") -> #VALUE!
A24: Statutory Charge - Interest Bearing | B24: =COUNTIFS([1]CCMS_CASE_TOTALS_TRUE!HA:HA,"<>0",[1]CCMS_CASE_TOTALS_TRUE!GO:GO,">0") -> #VALUE!
A25: Statutory Charge - Secured | B25: =COUNTIFS([1]CCMS_CASE_TOTALS_TRUE!GO:GO,">0",[1]CCMS_CASE_TOTALS_TRUE!HA:HA,"=0",[1]CCMS_CASE_TOTALS_TRUE!Q:Q,"Y") -> #VALUE!
A26: Statutory Charge - Unsecured | B26: =COUNTIFS([1]CCMS_CASE_TOTALS_TRUE!GO:GO,">0",[1]CCMS_CASE_TOTALS_TRUE!HA:HA,"=0",[1]CCMS_CASE_TOTALS_TRUE!Q:Q,"N") -> #VALUE!
B27: =SUM(B24:B26) -> #VALUE!
A30: Max final bill date | B30: =MAX([1]CCMS_CASE_TOTALS_TRUE!DJ:DJ) -> #REF!

Sheet MAIN WOFF MIG ERROR
A1: CCMS Third party report
B3: Total outstanding | F3: LAA Debt | J3: Third Party Debt
A4: Debt Type | B4: Total | C4: Principal Debt | D4: Interest (late charges) | F4: Total | G4: Principal Debt | H4: Interest (late charges) | J4: Total | K4: Principal Debt | L4: Interest (late charges)
A5: Contributions | B5: =SUM(C5:D5) -> #VALUE! | C5: =SUMIF([1]CCMS_CASE_TOTALS_TRUE!HV:HV,1,[1]CCMS_CASE_TOTALS_TRUE!GF:GF) -> #VALUE! | D5: =H5 -> #VALUE! | F5: =SUM(G5:H5) -> #VALUE! | G5: =SUMIF([1]CCMS_CASE_TOTALS_TRUE!HV:HV,1,[1]CCMS_CASE_TOTALS_TRUE!GK:GK) -> #VALUE! | H5: =SUMIF([1]CCMS_CASE_TOTALS_TRUE!HV:HV,1,[1]CCMS_CASE_TOTALS_TRUE!GW:GW) -> #VALUE! | J5: =B5-F5 -> #VALUE! | K5: =C5-G5 -> #VALUE! | L5: =D5-H5 -> #VALUE!
A6: Costs | B6: =SUM(C6:D6) -> #VALUE! | C6: =SUMIF([1]CCMS_CASE_TOTALS_TRUE!HV:HV,1,[1]CCMS_CASE_TOTALS_TRUE!GG:GG) -> #VALUE! | D6: =H6 -> #VALUE! | F6: =SUM(G6:H6) -> #VALUE! | G6: =SUMIF([1]CCMS_CASE_TOTALS_TRUE!HV:HV,1,[1]CCMS_CASE_TOTALS_TRUE!GL:GL) -> #VALUE! | H6: =SUMIF([1]CCMS_CASE_TOTALS_TRUE!HV:HV,1,[1]CCMS_CASE_TOTALS_TRUE!GX:GX) -> #VALUE! | J6: =B6-F6 -> #VALUE! | K6: =C6-G6 -> #VALUE! | L6: =D6-H6 -> #VALUE!
A7: Damages | B7: =SUM(C7:D7) -> #VALUE! | C7: =SUMIF([1]CCMS_CASE_TOTALS_TRUE!HV:HV,1,[1]CCMS_CASE_TOTALS_TRUE!GH:GH) -> #VALUE! | D7: =H7 -> #VALUE! | F7: =SUM(G7:H7) -> #VALUE! | G7: =SUMIF([1]CCMS_CASE_TOTALS_TRUE!HV:HV,1,[1]CCMS_CASE_TOTALS_TRUE!GM:GM) -> #VALUE! | H7: =SUMIF([1]CCMS_CASE_TOTALS_TRUE!HV:HV,1,[1]CCMS_CASE_TOTALS_TRUE!GY:GY) -> #VALUE! | J7: =B7-F7 -> #VALUE! | K7: =C7-G7 -> #VALUE! | L7: =D7-H7 -> #VALUE!
A8: Revocation | B8: =SUM(C8:D8) -> #VALUE! | C8: =SUMIF([1]CCMS_CASE_TOTALS_TRUE!HV:HV,1,[1]CCMS_CASE_TOTALS_TRUE!GI:GI) -> #VALUE! | D8: =H8 -> #VALUE! | F8: =SUM(G8:H8) -> #VALUE! | G8: =SUMIF([1]CCMS_CASE_TOTALS_TRUE!HV:HV,1,[1]CCMS_CASE_TOTALS_TRUE!GN:GN) -> #VALUE! | H8: =SUMIF([1]CCMS_CASE_TOTALS_TRUE!HV:HV,1,[1]CCMS_CASE_TOTALS_TRUE!GZ:GZ) -> #VALUE! | J8: =B8-F8 -> #VALUE! | K8: =C8-G8 -> #VALUE! | L8: =D8-H8 -> #VALUE!
A9: Statutory Charge - Interest Bearing | B9: =SUM(C9:D9) -> #VALUE! | C9: =SUMIFS([1]CCMS_CASE_TOTALS_TRUE!GJ:GJ,[1]CCMS_CASE_TOTALS_TRUE!HA:HA,"<>0",[1]CCMS_CASE_TOTALS_TRUE!HV:HV,1) -> #VALUE! | D9: =H9 -> #VALUE! | F9: =SUM(G9:H9) -> #VALUE! | G9: =SUMIFS([1]CCMS_CASE_TOTALS_TRUE!GO:GO,[1]CCMS_CASE_TOTALS_TRUE!HA:HA,"<>0",[1]CCMS_CASE_TOTALS_TRUE!HV:HV,1) -> #VALUE! | H9: =SUMIF([1]CCMS_CASE_TOTALS_TRUE!HV:HV,1,[1]CCMS_CASE_TOTALS_TRUE!HA:HA) -> #VALUE! | J9: =B9-F9 -> #VALUE! | K9: =C9-G9 -> #VALUE! | L9: =D9-H9 -> #VALUE!
A10: Statutory Charge - Secured | B10: =SUM(C10:D10) -> #VALUE! | C10: =SUMIFS([1]CCMS_CASE_TOTALS_TRUE!GJ:GJ,[1]CCMS_CASE_TOTALS_TRUE!HA:HA,"=0",[1]CCMS_CASE_TOTALS_TRUE!Q:Q,"Y",[1]CCMS_CASE_TOTALS_TRUE!HV:HV,1) -> #VALUE! | D10: =H10 -> 0 | F10: =SUM(G10:H10) -> #VALUE! | G10: =SUMIFS([1]CCMS_CASE_TOTALS_TRUE!GO:GO,[1]CCMS_CASE_TOTALS_TRUE!HA:HA,"=0",[1]CCMS_CASE_TOTALS_TRUE!Q:Q,"Y",[1]CCMS_CASE_TOTALS_TRUE!HV:HV,1) -> #VALUE! | H10: 0 | J10: =B10-F10 -> #VALUE! | K10: =C10-G10 -> #VALUE! | L10: =D10-H10 -> 0
A11: Statutory Charge - Unsecured | B11: =SUM(C11:D11) -> #VALUE! | C11: =SUMIFS([1]CCMS_CASE_TOTALS_TRUE!GJ:GJ,[1]CCMS_CASE_TOTALS_TRUE!HA:HA,"=0",[1]CCMS_CASE_TOTALS_TRUE!Q:Q,"N",[1]CCMS_CASE_TOTALS_TRUE!HV:HV,1) -> #VALUE! | D11: =H11 -> 0 | F11: =SUM(G11:H11) -> #VALUE! | G11: =SUMIFS([1]CCMS_CASE_TOTALS_TRUE!GO:GO,[1]CCMS_CASE_TOTALS_TRUE!HA:HA,"=0",[1]CCMS_CASE_TOTALS_TRUE!Q:Q,"N",[1]CCMS_CASE_TOTALS_TRUE!HV:HV,1) -> #VALUE! | H11: 0 | J11: =B11-F11 -> #VALUE! | K11: =C11-G11 -> #VALUE! | L11: =D11-H11 -> 0
A14: Total | B14: =SUM(B5:B13) -> #VALUE! | C14: =SUM(C5:C13) -> #VALUE! | D14: =SUM(D5:D13) -> #VALUE! | F14: =SUM(F5:F13) -> #VALUE! | G14: =SUM(G5:G13) -> #VALUE! | H14: =SUM(H5:H13) -> #VALUE! | J14: =SUM(J5:J13) -> #VALUE! | K14: =SUM(K5:K13) -> #VALUE! | L14: =SUM(L5:L13) -> #VALUE!
L16: =0-L14 -> #VALUE!

Sheet Reconciliation
B1: All CCMS Debt Balances
B2: Does not include unapplied income or credit memo's
C4: Civil | D4: Crime Higher | E4: Other | F4: Provider | G4: Staff Debt | I4: Total
B5: Principal | C5: ='All Debts by Type Summary'!C17 -> #VALUE! | D5: ='All Debts by Type Summary'!D17 -> #VALUE! | E5: ='All Debts by Type Summary'!E17 -> #VALUE! | F5: ='All Debts by Type Summary'!F17 -> #VALUE! | G5: ='All Debts by Type Summary'!G17 -> #VALUE! | I5: =SUM(C5:H5) -> #VALUE!
B6: Interest | C6: ='All Debts by Type Summary'!C19 -> #VALUE! | D6: ='All Debts by Type Summary'!D19 -> #VALUE! | E6: ='All Debts by Type Summary'!E19 -> #VALUE! | F6: ='All Debts by Type Summary'!F19 -> #VALUE! | G6: ='All Debts by Type Summary'!G19 -> #VALUE! | I6: =SUM(C6:H6) -> #VALUE!
B7: Total | C7: =SUM(C5:C6) -> #VALUE! | D7: =SUM(D5:D6) -> #VALUE! | E7: =SUM(E5:E6) -> #VALUE! | F7: =SUM(F5:F6) -> #VALUE! | G7: =SUM(G5:G6) -> #VALUE! | I7: =SUM(I5:I6) -> #VALUE!
B9: Civil Balances Reported Here
C11: Principal | D11: Interest
B12: Correctly linked Debts | C12: =SUM(#REF!) -> #REF! | D12: =SUM(#REF!) -> #REF!
B13: Migrated in error | C13: =SUM('Civil Debt Exceptions'!C21:G21) -> #REF! | D13: =SUM('Civil Debt Exceptions'!C23:G23) -> #REF!
B14: Not linked to a case | C14: =SUM('Civil Debt Exceptions'!C41:G41) -> #VALUE! | D14: =SUM('Civil Debt Exceptions'!C43:G43) -> #VALUE!
B16: Total | C16: =SUM(C12:C15) -> #REF! | D16: =SUM(D12:D15) -> #REF!
B17: Variance in Civil Balances | C17: =C16-C5 -> #REF! | D17: =D16-C6 -> #REF!

Sheet Age Profile
A1: All debt aging is derived from the date each civil case's funding completed (final bill date).
A3: Volume
B5: Debt Type
B6: Costs | C6: Damages | D6: Revocation | E6: Statutory Charge Bearing | F6: Statutory Charge Non-bearing
A7: 0-30 days | B7: =COUNTIFS([1]CCMS_CASE_TOTALS_TRUE!GL:GL,">0",[1]CCMS_CASE_TOTALS_TRUE!$J:$J,"<=30") -> #VALUE! | C7: =COUNTIFS([1]CCMS_CASE_TOTALS_TRUE!GM:GM,">0",[1]CCMS_CASE_TOTALS_TRUE!$J:$J,"<=30") -> #VALUE! | D7: =COUNTIFS([1]CCMS_CASE_TOTALS_TRUE!GN:GN,">0",[1]CCMS_CASE_TOTALS_TRUE!$J:$J,"<=30") -> #VALUE! | E7: =COUNTIFS([1]CCMS_CASE_TOTALS_TRUE!GO:GO,">0",[1]CCMS_CASE_TOTALS_TRUE!HA:HA,"<>0",[1]CCMS_CASE_TOTALS_TRUE!$J:$J,"<=30") -> #VALUE! | F7: =COUNTIFS([1]CCMS_CASE_TOTALS_TRUE!GO:GO,">0",[1]CCMS_CASE_TOTALS_TRUE!HA:HA,"=0",[1]CCMS_CASE_TOTALS_TRUE!$J:$J,"<=30") -> #VALUE!
A8: 31-60 days | B8: =COUNTIFS([1]CCMS_CASE_TOTALS_TRUE!GL:GL,">0",[1]CCMS_CASE_TOTALS_TRUE!$J:$J,"<=60")-SUM(B$7) -> #VALUE! | C8: =COUNTIFS([1]CCMS_CASE_TOTALS_TRUE!GM:GM,">0",[1]CCMS_CASE_TOTALS_TRUE!$J:$J,"<=60")-SUM(C$7) -> #VALUE! | D8: =COUNTIFS([1]CCMS_CASE_TOTALS_TRUE!GN:GN,">0",[1]CCMS_CASE_TOTALS_TRUE!$J:$J,"<=60")-SUM(D$7) -> #VALUE! | E8: =COUNTIFS([1]CCMS_CASE_TOTALS_TRUE!GO:GO,">0",[1]CCMS_CASE_TOTALS_TRUE!HA:HA,"<>0",[1]CCMS_CASE_TOTALS_TRUE!$J:$J,"<=60")-SUM(E$7) -> #VALUE! | F8: =COUNTIFS([1]CCMS_CASE_TOTALS_TRUE!GO:GO,">0",[1]CCMS_CASE_TOTALS_TRUE!HA:HA,"=0",[1]CCMS_CASE_TOTALS_TRUE!$J:$J,"<=60")-SUM(F$7) -> #VALUE!
A9: 60-90 days | B9: =COUNTIFS([1]CCMS_CASE_TOTALS_TRUE!GL:GL,">0",[1]CCMS_CASE_TOTALS_TRUE!$J:$J,"<=90")-SUM(B$7:B8) -> #VALUE! | C9: =COUNTIFS([1]CCMS_CASE_TOTALS_TRUE!GM:GM,">0",[1]CCMS_CASE_TOTALS_TRUE!$J:$J,"<=90")-SUM(C$7:C8) -> #VALUE! | D9: =COUNTIFS([1]CCMS_CASE_TOTALS_TRUE!GN:GN,">0",[1]CCMS_CASE_TOTALS_TRUE!$J:$J,"<=90")-SUM(D$7:D8) -> #VALUE! | E9: =COUNTIFS([1]CCMS_CASE_TOTALS_TRUE!GO:GO,">0",[1]CCMS_CASE_TOTALS_TRUE!HA:HA,"<>0",[1]CCMS_CASE_TOTALS_TRUE!$J:$J,"<=90")-SUM(E$7:E8) -> #VALUE! | F9: =COUNTIFS([1]CCMS_CASE_TOTALS_TRUE!GO:GO,">0",[1]CCMS_CASE_TOTALS_TRUE!HA:HA,"=0",[1]CCMS_CASE_TOTALS_TRUE!$J:$J,"<=90")-SUM(F$7:F8) -> #VALUE!
A10: Under 1 Year | B10: =COUNTIFS([1]CCMS_CASE_TOTALS_TRUE!GL:GL,">0",[1]CCMS_CASE_TOTALS_TRUE!$J:$J,"<=365")-SUM(B$7:B9) -> #VALUE! | C10: =COUNTIFS([1]CCMS_CASE_TOTALS_TRUE!GM:GM,">0",[1]CCMS_CASE_TOTALS_TRUE!$J:$J,"<=365")-SUM(C$7:C9) -> #VALUE! | D10: =COUNTIFS([1]CCMS_CASE_TOTALS_TRUE!GN:GN,">0",[1]CCMS_CASE_TOTALS_TRUE!$J:$J,"<=365")-SUM(D$7:D9) -> #VALUE! | E10: =COUNTIFS([1]CCMS_CASE_TOTALS_TRUE!GO:GO,">0",[1]CCMS_CASE_TOTALS_TRUE!HA:HA,"<>0",[1]CCMS_CASE_TOTALS_TRUE!$J:$J,"<=365")-SUM(E$7:E9) -> #VALUE! | F10: =COUNTIFS([1]CCMS_CASE_TOTALS_TRUE!GO:GO,">0",[1]CCMS_CASE_TOTALS_TRUE!HA:HA,"=0",[1]CCMS_CASE_TOTALS_TRUE!$J:$J,"<=365")-SUM(F$7:F9) -> #VALUE!
A11: 1- 3years | B11: =COUNTIFS([1]CCMS_CASE_TOTALS_TRUE!GL:GL,">0",[1]CCMS_CASE_TOTALS_TRUE!$J:$J,"<=1095")-SUM(B$7:B10) -> #VALUE! | C11: =COUNTIFS([1]CCMS_CASE_TOTALS_TRUE!GM:GM,">0",[1]CCMS_CASE_TOTALS_TRUE!$J:$J,"<=1095")-SUM(C$7:C10) -> #VALUE! | D11: =COUNTIFS([1]CCMS_CASE_TOTALS_TRUE!GN:GN,">0",[1]CCMS_CASE_TOTALS_TRUE!$J:$J,"<=1095")-SUM(D$7:D10) -> #VALUE! | E11: =COUNTIFS([1]CCMS_CASE_TOTALS_TRUE!GO:GO,">0",[1]CCMS_CASE_TOTALS_TRUE!HA:HA,"<>0",[1]CCMS_CASE_TOTALS_TRUE!$J:$J,"<=1095")-SUM(E$7:E10) -> #VALUE! | F11: =COUNTIFS([1]CCMS_CASE_TOTALS_TRUE!GO:GO,">0",[1]CCMS_CASE_TOTALS_TRUE!HA:HA,"=0",[1]CCMS_CASE_TOTALS_TRUE!$J:$J,"<=1095")-SUM(F$7:F10) -> #VALUE!
A12: 3-5 Years | B12: =COUNTIFS([1]CCMS_CASE_TOTALS_TRUE!GL:GL,">0",[1]CCMS_CASE_TOTALS_TRUE!$J:$J,"<=1825")-SUM(B$7:B11) -> #VALUE! | C12: =COUNTIFS([1]CCMS_CASE_TOTALS_TRUE!GM:GM,">0",[1]CCMS_CASE_TOTALS_TRUE!$J:$J,"<=1825")-SUM(C$7:C11) -> #VALUE! | D12: =COUNTIFS([1]CCMS_CASE_TOTALS_TRUE!GN:GN,">0",[1]CCMS_CASE_TOTALS_TRUE!$J:$J,"<=1825")-SUM(D$7:D11) -> #VALUE! | E12: =COUNTIFS([1]CCMS_CASE_TOTALS_TRUE!GO:GO,">0",[1]CCMS_CASE_TOTALS_TRUE!HA:HA,"<>0",[1]CCMS_CASE_TOTALS_TRUE!$J:$J,"<=1825")-SUM(E$7:E11) -> #VALUE! | F12: =COUNTIFS([1]CCMS_CASE_TOTALS_TRUE!GO:GO,">0",[1]CCMS_CASE_TOTALS_TRUE!HA:HA,"=0",[1]CCMS_CASE_TOTALS_TRUE!$J:$J,"<=1825")-SUM(F$7:F11) -> #VALUE!
A13: 5-10 Years | B13: =COUNTIFS([1]CCMS_CASE_TOTALS_TRUE!GL:GL,">0",[1]CCMS_CASE_TOTALS_TRUE!$J:$J,"<=3650")-SUM(B$7:B12) -> #VALUE! | C13: =COUNTIFS([1]CCMS_CASE_TOTALS_TRUE!GM:GM,">0",[1]CCMS_CASE_TOTALS_TRUE!$J:$J,"<=3650")-SUM(C$7:C12) -> #VALUE! | D13: =COUNTIFS([1]CCMS_CASE_TOTALS_TRUE!GN:GN,">0",[1]CCMS_CASE_TOTALS_TRUE!$J:$J,"<=3650")-SUM(D$7:D12) -> #VALUE! | E13: =COUNTIFS([1]CCMS_CASE_TOTALS_TRUE!GO:GO,">0",[1]CCMS_CASE_TOTALS_TRUE!HA:HA,"<>0",[1]CCMS_CASE_TOTALS_TRUE!$J:$J,"<=3650")-SUM(E$7:E12) -> #VALUE! | F13: =COUNTIFS([1]CCMS_CASE_TOTALS_TRUE!GO:GO,">0",[1]CCMS_CASE_TOTALS_TRUE!HA:HA,"=0",[1]CCMS_CASE_TOTALS_TRUE!$J:$J,"<=3650")-SUM(F$7:F12) -> #VALUE!
A14: 10-15 Years | B14: =COUNTIFS([1]CCMS_CASE_TOTALS_TRUE!GL:GL,">0",[1]CCMS_CASE_TOTALS_TRUE!$J:$J,"<=5475")-SUM(B$7:B13) -> #VALUE! | C14: =COUNTIFS([1]CCMS_CASE_TOTALS_TRUE!GM:GM,">0",[1]CCMS_CASE_TOTALS_TRUE!$J:$J,"<=5475")-SUM(C$7:C13) -> #VALUE! | D14: =COUNTIFS([1]CCMS_CASE_TOTALS_TRUE!GN:GN,">0",[1]CCMS_CASE_TOTALS_TRUE!$J:$J,"<=5475")-SUM(D$7:D13) -> #VALUE! | E14: =COUNTIFS([1]CCMS_CASE_TOTALS_TRUE!GO:GO,">0",[1]CCMS_CASE_TOTALS_TRUE!HA:HA,"<>0",[1]CCMS_CASE_TOTALS_TRUE!$J:$J,"<=5475")-SUM(E$7:E13) -> #VALUE! | F14: =COUNTIFS([1]CCMS_CASE_TOTALS_TRUE!GO:GO,">0",[1]CCMS_CASE_TOTALS_TRUE!HA:HA,"=0",[1]CCMS_CASE_TOTALS_TRUE!$J:$J,"<=5475")-SUM(F$7:F13) -> #VALUE!
A15: 15-20 Years | B15: =COUNTIFS([1]CCMS_CASE_TOTALS_TRUE!GL:GL,">0",[1]CCMS_CASE_TOTALS_TRUE!$J:$J,"<=7300")-SUM(B$7:B14) -> #VALUE! | C15: =COUNTIFS([1]CCMS_CASE_TOTALS_TRUE!GM:GM,">0",[1]CCMS_CASE_TOTALS_TRUE!$J:$J,"<=7300")-SUM(C$7:C14) -> #VALUE! | D15: =COUNTIFS([1]CCMS_CASE_TOTALS_TRUE!GN:GN,">0",[1]CCMS_CASE_TOTALS_TRUE!$J:$J,"<=7300")-SUM(D$7:D14) -> #VALUE! | E15: =COUNTIFS([1]CCMS_CASE_TOTALS_TRUE!GO:GO,">0",[1]CCMS_CASE_TOTALS_TRUE!HA:HA,"<>0",[1]CCMS_CASE_TOTALS_TRUE!$J:$J,"<=7300")-SUM(E$7:E14) -> #VALUE! | F15: =COUNTIFS([1]CCMS_CASE_TOTALS_TRUE!GO:GO,">0",[1]CCMS_CASE_TOTALS_TRUE!HA:HA,"=0",[1]CCMS_CASE_TOTALS_TRUE!$J:$J,"<=7300")-SUM(F$7:F14) -> #VALUE!
A16: 20+ Years | B16: =COUNTIFS([1]CCMS_CASE_TOTALS_TRUE!GL:GL,">0",[1]CCMS_CASE_TOTALS_TRUE!$J:$J,">7300") -> #VALUE! | C16: =COUNTIFS([1]CCMS_CASE_TOTALS_TRUE!GM:GM,">0",[1]CCMS_CASE_TOTALS_TRUE!$J:$J,">7300") -> #VALUE! | D16: =COUNTIFS([1]CCMS_CASE_TOTALS_TRUE!GN:GN,">0",[1]CCMS_CASE_TOTALS_TRUE!$J:$J,">7300") -> #VALUE! | E16: =COUNTIFS([1]CCMS_CASE_TOTALS_TRUE!GO:GO,">0",[1]CCMS_CASE_TOTALS_TRUE!HA:HA,"<>0",[1]CCMS_CASE_TOTALS_TRUE!$J:$J,">7300") -> #VALUE! | F16: =COUNTIFS([1]CCMS_CASE_TOTALS_TRUE!GO:GO,">0",[1]CCMS_CASE_TOTALS_TRUE!HA:HA,"=0",[1]CCMS_CASE_TOTALS_TRUE!$J:$J,">7300") -> #VALUE!
A17: Total | B17: =SUM(B7:B16) -> #VALUE! | C17: =SUM(C7:C16) -> #VALUE! | D17: =SUM(D7:D16) -> #VALUE! | E17: =SUM(E7:E16) -> #VALUE! | F17: =SUM(F7:F16) -> #VALUE!
A19: Principal Value | H19: Interest
B21: Debt Type
B22: Costs | C22: Damages | D22: Revocation | E22: Statutory Charge Bearing | F22: Statutory Charge Non-bearing | H22: Statutory Charge Bearing
A23: 0-30 days | B23: =SUMIFS([1]CCMS_CASE_TOTALS_TRUE!GL:GL,[1]CCMS_CASE_TOTALS_TRUE!GL:GL,">0",[1]CCMS_CASE_TOTALS_TRUE!$J:$J,"<=30") -> #VALUE! | C23: =SUMIFS([1]CCMS_CASE_TOTALS_TRUE!GM:GM,[1]CCMS_CASE_TOTALS_TRUE!GM:GM,">0",[1]CCMS_CASE_TOTALS_TRUE!$J:$J,"<=30") -> #VALUE! | D23: =SUMIFS([1]CCMS_CASE_TOTALS_TRUE!GN:GN,[1]CCMS_CASE_TOTALS_TRUE!GN:GN,">0",[1]CCMS_CASE_TOTALS_TRUE!$J:$J,"<=30") -> #VALUE! | E23: =SUMIFS([1]CCMS_CASE_TOTALS_TRUE!GO:GO,[1]CCMS_CASE_TOTALS_TRUE!$J:$J,"<=30",[1]CCMS_CASE_TOTALS_TRUE!HA:HA,"<>0") -> #VALUE! | F23: =SUMIFS([1]CCMS_CASE_TOTALS_TRUE!GO:GO,[1]CCMS_CASE_TOTALS_TRUE!GO:GO,"<>0",[1]CCMS_CASE_TOTALS_TRUE!$J:$J,"<=30",[1]CCMS_CASE_TOTALS_TRUE!HA:HA,"=0") -> #VALUE! | H23: =SUMIFS([1]CCMS_CASE_TOTALS_TRUE!HA:HA,[1]CCMS_CASE_TOTALS_TRUE!HA:HA,"<>0",[1]CCMS_CASE_TOTALS_TRUE!$J:$J,"<=30") -> #VALUE!
A24: 31-60 days | B24: =SUMIFS([1]CCMS_CASE_TOTALS_TRUE!GL:GL,[1]CCMS_CASE_TOTALS_TRUE!GL:GL,">0",[1]CCMS_CASE_TOTALS_TRUE!$J:$J,"<=60")-SUM(B$23) -> #VALUE! | C24: =SUMIFS([1]CCMS_CASE_TOTALS_TRUE!GM:GM,[1]CCMS_CASE_TOTALS_TRUE!GM:GM,">0",[1]CCMS_CASE_TOTALS_TRUE!$J:$J,"<=60")-SUM(C$23) -> #VALUE! | D24: =SUMIFS([1]CCMS_CASE_TOTALS_TRUE!GN:GN,[1]CCMS_CASE_TOTALS_TRUE!GN:GN,">0",[1]CCMS_CASE_TOTALS_TRUE!$J:$J,"<=60")-SUM(D$23) -> #VALUE! | E24: =SUMIFS([1]CCMS_CASE_TOTALS_TRUE!GO:GO,[1]CCMS_CASE_TOTALS_TRUE!$J:$J,"<=60",[1]CCMS_CASE_TOTALS_TRUE!HA:HA,"<>0")-SUM(E$23) -> #VALUE! | F24: =SUMIFS([1]CCMS_CASE_TOTALS_TRUE!GO:GO,[1]CCMS_CASE_TOTALS_TRUE!GO:GO,"<>0",[1]CCMS_CASE_TOTALS_TRUE!$J:$J,"<=60",[1]CCMS_CASE_TOTALS_TRUE!HA:HA,"=0")-SUM(F$23) -> #VALUE! | H24: =SUMIFS([1]CCMS_CASE_TOTALS_TRUE!HA:HA,[1]CCMS_CASE_TOTALS_TRUE!HA:HA,"<>0",[1]CCMS_CASE_TOTALS_TRUE!$J:$J,"<=60")-SUM(H$23) -> #VALUE!
A25: 60-90 days | B25: =SUMIFS([1]CCMS_CASE_TOTALS_TRUE!GL:GL,[1]CCMS_CASE_TOTALS_TRUE!GL:GL,">0",[1]CCMS_CASE_TOTALS_TRUE!$J:$J,"<=90")-SUM(B$23:B24) -> #VALUE! | C25: =SUMIFS([1]CCMS_CASE_TOTALS_TRUE!GM:GM,[1]CCMS_CASE_TOTALS_TRUE!GM:GM,">0",[1]CCMS_CASE_TOTALS_TRUE!$J:$J,"<=90")-SUM(C$23:C24) -> #VALUE! | D25: =SUMIFS([1]CCMS_CASE_TOTALS_TRUE!GN:GN,[1]CCMS_CASE_TOTALS_TRUE!GN:GN,">0",[1]CCMS_CASE_TOTALS_TRUE!$J:$J,"<=90")-SUM(D$23:D24) -> #VALUE! | E25: =SUMIFS([1]CCMS_CASE_TOTALS_TRUE!GO:GO,[1]CCMS_CASE_TOTALS_TRUE!$J:$J,"<=90",[1]CCMS_CASE_TOTALS_TRUE!HA:HA,"<>0")-SUM(E$23:E24) -> #VALUE! | F25: =SUMIFS([1]CCMS_CASE_TOTALS_TRUE!GO:GO,[1]CCMS_CASE_TOTALS_TRUE!GO:GO,"<>0",[1]CCMS_CASE_TOTALS_TRUE!$J:$J,"<=90",[1]CCMS_CASE_TOTALS_TRUE!HA:HA,"=0")-SUM(F$23:F24) -> #VALUE! | H25: =SUMIFS([1]CCMS_CASE_TOTALS_TRUE!HA:HA,[1]CCMS_CASE_TOTALS_TRUE!HA:HA,"<>0",[1]CCMS_CASE_TOTALS_TRUE!$J:$J,"<=90")-SUM(H$23:H24) -> #VALUE!
A26: Under 1 Year | B26: =SUMIFS([1]CCMS_CASE_TOTALS_TRUE!GL:GL,[1]CCMS_CASE_TOTALS_TRUE!GL:GL,">0",[1]CCMS_CASE_TOTALS_TRUE!$J:$J,"<=365")-SUM(B$23:B25) -> #VALUE! | C26: =SUMIFS([1]CCMS_CASE_TOTALS_TRUE!GM:GM,[1]CCMS_CASE_TOTALS_TRUE!GM:GM,">0",[1]CCMS_CASE_TOTALS_TRUE!$J:$J,"<=365")-SUM(C$23:C25) -> #VALUE! | D26: =SUMIFS([1]CCMS_CASE_TOTALS_TRUE!GN:GN,[1]CCMS_CASE_TOTALS_TRUE!GN:GN,">0",[1]CCMS_CASE_TOTALS_TRUE!$J:$J,"<=365")-SUM(D$23:D25) -> #VALUE! | E26: =SUMIFS([1]CCMS_CASE_TOTALS_TRUE!GO:GO,[1]CCMS_CASE_TOTALS_TRUE!$J:$J,"<=365",[1]CCMS_CASE_TOTALS_TRUE!HA:HA,"<>0")-SUM(E$23:E25) -> #VALUE! | F26: =SUMIFS([1]CCMS_CASE_TOTALS_TRUE!GO:GO,[1]CCMS_CASE_TOTALS_TRUE!GO:GO,"<>0",[1]CCMS_CASE_TOTALS_TRUE!$J:$J,"<=365",[1]CCMS_CASE_TOTALS_TRUE!HA:HA,"=0")-SUM(F$23:F25) -> #VALUE! | H26: =SUMIFS([1]CCMS_CASE_TOTALS_TRUE!HA:HA,[1]CCMS_CASE_TOTALS_TRUE!HA:HA,"<>0",[1]CCMS_CASE_TOTALS_TRUE!$J:$J,"<=365")-SUM(H$23:H25) -> #VALUE!
A27: 1- 3years | B27: =SUMIFS([1]CCMS_CASE_TOTALS_TRUE!GL:GL,[1]CCMS_CASE_TOTALS_TRUE!GL:GL,">0",[1]CCMS_CASE_TOTALS_TRUE!$J:$J,"<=1095")-SUM(B$23:B26) -> #VALUE! | C27: =SUMIFS([1]CCMS_CASE_TOTALS_TRUE!GM:GM,[1]CCMS_CASE_TOTALS_TRUE!GM:GM,">0",[1]CCMS_CASE_TOTALS_TRUE!$J:$J,"<=1095")-SUM(C$23:C26) -> #VALUE! | D27: =SUMIFS([1]CCMS_CASE_TOTALS_TRUE!GN:GN,[1]CCMS_CASE_TOTALS_TRUE!GN:GN,">0",[1]CCMS_CASE_TOTALS_TRUE!$J:$J,"<=1095")-SUM(D$23:D26) -> #VALUE! | E27: =SUMIFS([1]CCMS_CASE_TOTALS_TRUE!GO:GO,[1]CCMS_CASE_TOTALS_TRUE!$J:$J,"<=1095",[1]CCMS_CASE_TOTALS_TRUE!HA:HA,"<>0")-SUM(E$23:E26) -> #VALUE! | F27: =SUMIFS([1]CCMS_CASE_TOTALS_TRUE!GO:GO,[1]CCMS_CASE_TOTALS_TRUE!GO:GO,"<>0",[1]CCMS_CASE_TOTALS_TRUE!$J:$J,"<=1095",[1]CCMS_CASE_TOTALS_TRUE!HA:HA,"=0")-SUM(F$23:F26) -> #VALUE! | H27: =SUMIFS([1]CCMS_CASE_TOTALS_TRUE!HA:HA,[1]CCMS_CASE_TOTALS_TRUE!HA:HA,"<>0",[1]CCMS_CASE_TOTALS_TRUE!$J:$J,"<=1095")-SUM(H$23:H26) -> #VALUE!
A28: 3-5 Years | B28: =SUMIFS([1]CCMS_CASE_TOTALS_TRUE!GL:GL,[1]CCMS_CASE_TOTALS_TRUE!GL:GL,">0",[1]CCMS_CASE_TOTALS_TRUE!$J:$J,"<=1825")-SUM(B$23:B27) -> #VALUE! | C28: =SUMIFS([1]CCMS_CASE_TOTALS_TRUE!GM:GM,[1]CCMS_CASE_TOTALS_TRUE!GM:GM,">0",[1]CCMS_CASE_TOTALS_TRUE!$J:$J,"<=1825")-SUM(C$23:C27) -> #VALUE! | D28: =SUMIFS([1]CCMS_CASE_TOTALS_TRUE!GN:GN,[1]CCMS_CASE_TOTALS_TRUE!GN:GN,">0",[1]CCMS_CASE_TOTALS_TRUE!$J:$J,"<=1825")-SUM(D$23:D27) -> #VALUE! | E28: =SUMIFS([1]CCMS_CASE_TOTALS_TRUE!GO:GO,[1]CCMS_CASE_TOTALS_TRUE!$J:$J,"<=1825",[1]CCMS_CASE_TOTALS_TRUE!HA:HA,"<>0")-SUM(E$23:E27) -> #VALUE! | F28: =SUMIFS([1]CCMS_CASE_TOTALS_TRUE!GO:GO,[1]CCMS_CASE_TOTALS_TRUE!GO:GO,"<>0",[1]CCMS_CASE_TOTALS_TRUE!$J:$J,"<=1825",[1]CCMS_CASE_TOTALS_TRUE!HA:HA,"=0")-SUM(F$23:F27) -> #VALUE! | H28: =SUMIFS([1]CCMS_CASE_TOTALS_TRUE!HA:HA,[1]CCMS_CASE_TOTALS_TRUE!HA:HA,"<>0",[1]CCMS_CASE_TOTALS_TRUE!$J:$J,"<=1825")-SUM(H$23:H27) -> #VALUE!
A29: 5-10 Years | B29: =SUMIFS([1]CCMS_CASE_TOTALS_TRUE!GL:GL,[1]CCMS_CASE_TOTALS_TRUE!GL:GL,">0",[1]CCMS_CASE_TOTALS_TRUE!$J:$J,"<=3650")-SUM(B$23:B28) -> #VALUE! | C29: =SUMIFS([1]CCMS_CASE_TOTALS_TRUE!GM:GM,[1]CCMS_CASE_TOTALS_TRUE!GM:GM,">0",[1]CCMS_CASE_TOTALS_TRUE!$J:$J,"<=3650")-SUM(C$23:C28) -> #VALUE! | D29: =SUMIFS([1]CCMS_CASE_TOTALS_TRUE!GN:GN,[1]CCMS_CASE_TOTALS_TRUE!GN:GN,">0",[1]CCMS_CASE_TOTALS_TRUE!$J:$J,"<=3650")-SUM(D$23:D28) -> #VALUE! | E29: =SUMIFS([1]CCMS_CASE_TOTALS_TRUE!GO:GO,[1]CCMS_CASE_TOTALS_TRUE!$J:$J,"<=3650",[1]CCMS_CASE_TOTALS_TRUE!HA:HA,"<>0")-SUM(E$23:E28) -> #VALUE! | F29: =SUMIFS([1]CCMS_CASE_TOTALS_TRUE!GO:GO,[1]CCMS_CASE_TOTALS_TRUE!GO:GO,"<>0",[1]CCMS_CASE_TOTALS_TRUE!$J:$J,"<=3650",[1]CCMS_CASE_TOTALS_TRUE!HA:HA,"=0")-SUM(F$23:F28) -> #VALUE! | H29: =SUMIFS([1]CCMS_CASE_TOTALS_TRUE!HA:HA,[1]CCMS_CASE_TOTALS_TRUE!HA:HA,"<>0",[1]CCMS_CASE_TOTALS_TRUE!$J:$J,"<=3650")-SUM(H$23:H28) -> #VALUE!
A30: 10-15 Years | B30: =SUMIFS([1]CCMS_CASE_TOTALS_TRUE!GL:GL,[1]CCMS_CASE_TOTALS_TRUE!GL:GL,">0",[1]CCMS_CASE_TOTALS_TRUE!$J:$J,"<=5475")-SUM(B$23:B29) -> #VALUE! | C30: =SUMIFS([1]CCMS_CASE_TOTALS_TRUE!GM:GM,[1]CCMS_CASE_TOTALS_TRUE!GM:GM,">0",[1]CCMS_CASE_TOTALS_TRUE!$J:$J,"<=5475")-SUM(C$23:C29) -> #VALUE! | D30: =SUMIFS([1]CCMS_CASE_TOTALS_TRUE!GN:GN,[1]CCMS_CASE_TOTALS_TRUE!GN:GN,">0",[1]CCMS_CASE_TOTALS_TRUE!$J:$J,"<=5475")-SUM(D$23:D29) -> #VALUE! | E30: =SUMIFS([1]CCMS_CASE_TOTALS_TRUE!GO:GO,[1]CCMS_CASE_TOTALS_TRUE!$J:$J,"<=5475",[1]CCMS_CASE_TOTALS_TRUE!HA:HA,"<>0")-SUM(E$23:E29) -> #VALUE! | F30: =SUMIFS([1]CCMS_CASE_TOTALS_TRUE!GO:GO,[1]CCMS_CASE_TOTALS_TRUE!GO:GO,"<>0",[1]CCMS_CASE_TOTALS_TRUE!$J:$J,"<=5475",[1]CCMS_CASE_TOTALS_TRUE!HA:HA,"=0")-SUM(F$23:F29) -> #VALUE! | H30: =SUMIFS([1]CCMS_CASE_TOTALS_TRUE!HA:HA,[1]CCMS_CASE_TOTALS_TRUE!HA:HA,"<>0",[1]CCMS_CASE_TOTALS_TRUE!$J:$J,"<=5475")-SUM(H$23:H29) -> #VALUE!
A31: 15-20 Years | B31: =SUMIFS([1]CCMS_CASE_TOTALS_TRUE!GL:GL,[1]CCMS_CASE_TOTALS_TRUE!GL:GL,">0",[1]CCMS_CASE_TOTALS_TRUE!$J:$J,"<=7300")-SUM(B$23:B30) -> #VALUE! | C31: =SUMIFS([1]CCMS_CASE_TOTALS_TRUE!GM:GM,[1]CCMS_CASE_TOTALS_TRUE!GM:GM,">0",[1]CCMS_CASE_TOTALS_TRUE!$J:$J,"<=7300")-SUM(C$23:C30) -> #VALUE! | D31: =SUMIFS([1]CCMS_CASE_TOTALS_TRUE!GN:GN,[1]CCMS_CASE_TOTALS_TRUE!GN:GN,">0",[1]CCMS_CASE_TOTALS_TRUE!$J:$J,"<=7300")-SUM(D$23:D30) -> #VALUE! | E31: =SUMIFS([1]CCMS_CASE_TOTALS_TRUE!GO:GO,[1]CCMS_CASE_TOTALS_TRUE!$J:$J,"<=7300",[1]CCMS_CASE_TOTALS_TRUE!HA:HA,"<>0")-SUM(E$23:E30) -> #VALUE! | F31: =SUMIFS([1]CCMS_CASE_TOTALS_TRUE!GO:GO,[1]CCMS_CASE_TOTALS_TRUE!GO:GO,"<>0",[1]CCMS_CASE_TOTALS_TRUE!$J:$J,"<=7300",[1]CCMS_CASE_TOTALS_TRUE!HA:HA,"=0")-SUM(F$23:F30) -> #VALUE! | H31: =SUMIFS([1]CCMS_CASE_TOTALS_TRUE!HA:HA,[1]CCMS_CASE_TOTALS_TRUE!HA:HA,"<>0",[1]CCMS_CASE_TOTALS_TRUE!$J:$J,"<=7300")-SUM(H$23:H30) -> #VALUE!
A32: 20+ Years | B32: =SUMIFS([1]CCMS_CASE_TOTALS_TRUE!GL:GL,[1]CCMS_CASE_TOTALS_TRUE!GL:GL,">0")-SUM(B23:B31) -> #VALUE! | C32: =SUMIFS([1]CCMS_CASE_TOTALS_TRUE!GM:GM,[1]CCMS_CASE_TOTALS_TRUE!GM:GM,">0")-SUM(C23:C31) -> #VALUE! | D32: =SUMIFS([1]CCMS_CASE_TOTALS_TRUE!GN:GN,[1]CCMS_CASE_TOTALS_TRUE!GN:GN,">0")-SUM(D23:D31) -> #VALUE! | E32: =SUMIFS([1]CCMS_CASE_TOTALS_TRUE!GO:GO,[1]CCMS_CASE_TOTALS_TRUE!HA:HA,"<>0")-SUM(E23:E31) -> #VALUE! | F32: =SUMIFS([1]CCMS_CASE_TOTALS_TRUE!GO:GO,[1]CCMS_CASE_TOTALS_TRUE!GO:GO,"<>0",[1]CCMS_CASE_TOTALS_TRUE!HA:HA,"=0")-SUM(F23:F31) -> #VALUE! | H32: =SUMIFS([1]CCMS_CASE_TOTALS_TRUE!HA:HA,[1]CCMS_CASE_TOTALS_TRUE!HA:HA,"<>0")-SUM(H23:H31) -> #VALUE!
A33: Total | B33: =SUM(B23:B32) -> #VALUE! | C33: =SUM(C23:C32) -> #VALUE! | D33: =SUM(D23:D32) -> #VALUE! | E33: =SUM(E23:E32) -> #VALUE! | F33: =SUM(F23:F32) -> #VALUE! | H33: =SUM(H23:H32) -> #VALUE!
A34: CHECKSUM | B34: =MAIN!G6-'Age Profile'!B33 -> #REF! | C34: =C33-MAIN!G7 -> #VALUE! | D34: =D33-MAIN!G8 -> #VALUE! | E34: =E33-MAIN!G9 -> #VALUE! | F34: =MAIN!G10+MAIN!G11-F33 -> #VALUE! | H34: =MAIN!H9-H33 -> #REF!

Sheet Civil Movement Report
B1: Principal Debt
B3: LAA Principal Debt
B5: Transaction Type | C5: Contributions | D5: Costs | E5: Damages | F5: Revocation | G5: Statutory charge | I5: Total
B6: LAA Debt invoices | C6: =#REF! -> #REF! | D6: =#REF! -> #REF! | E6: =#REF! -> #REF! | F6: =#REF! -> #REF! | G6: =#REF! -> #REF! | I6: =SUM(C6:H6) -> #REF!
B7: LAA Adjustment: Other Increasing Debt | C7: =#REF! -> #REF! | D7: =#REF! -> #REF! | E7: =#REF! -> #REF! | F7: =#REF! -> #REF! | G7: =#REF! -> #REF! | I7: =SUM(C7:H7) -> #REF!
B8: LAA Adjustments: Other Lowering Debt | C8: =#REF! -> #REF! | D8: =#REF! -> #REF! | E8: =#REF! -> #REF! | F8: =#REF! -> #REF! | G8: =#REF! -> #REF! | I8: =SUM(C8:H8) -> #REF!
B9: LAA Adjustments: Writeoff Debt | C9: =#REF! -> #REF! | D9: =#REF! -> #REF! | E9: =#REF! -> #REF! | F9: =#REF! -> #REF! | G9: =#REF! -> #REF! | I9: =SUM(C9:H9) -> #REF!
B10: LAA Adjustments: Writedown Debt | C10: =#REF! -> #REF! | D10: =#REF! -> #REF! | E10: =#REF! -> #REF! | F10: =#REF! -> #REF! | G10: =#REF! -> #REF! | I10: =SUM(C10:H10) -> #REF!
B11: LAA Cash receipts: Debt | C11: =#REF! -> #REF! | D11: =#REF! -> #REF! | E11: =#REF! -> #REF! | F11: =#REF! -> #REF! | G11: =#REF! -> #REF! | I11: =SUM(C11:H11) -> #REF!
B12: LAA Credit memo: Debt | C12: =#REF! -> #REF! | D12: =#REF! -> #REF! | E12: =#REF! -> #REF! | F12: =#REF! -> #REF! | G12: =#REF! -> #REF! | I12: =SUM(C12:H12) -> #REF!
B14: Balance Principal | C14: =C6-SUM(C7:C12) -> #REF! | D14: =D6-SUM(D7:D12) -> #REF! | E14: =E6-SUM(E7:E12) -> #REF! | F14: =F6-SUM(F7:F12) -> #REF! | G14: =G6-SUM(G7:G12) -> #REF! | I14: =I6-SUM(I7:I12) -> #REF!
B15: CHECKSUM | C15: =#REF!-C14 -> #REF! | D15: =#REF!-D14 -> #REF! | E15: =#REF!-E14 -> #REF! | F15: =#REF!-F14 -> #REF! | G15: =#REF!-G14 -> #REF! | I15: =#REF!-I14 -> #REF!
B17: Third Party Principal Debt
B19: Transaction Type | C19: Contributions | D19: Costs | E19: Damages | F19: Revocation | G19: Statutory charge | I19: Total
B20: Third Debt invoices | C20: =#REF!+'Civil Debt Exceptions'!C8+'Civil Debt Exceptions'!C28 -> #REF! | D20: =#REF!+'Civil Debt Exceptions'!D8+'Civil Debt Exceptions'!D28 -> #REF! | E20: =#REF!+'Civil Debt Exceptions'!E8+'Civil Debt Exceptions'!E28 -> #REF! | F20: =#REF!+'Civil Debt Exceptions'!F8+'Civil Debt Exceptions'!F28 -> #REF! | G20: =#REF!+'Civil Debt Exceptions'!G8+'Civil Debt Exceptions'!G28 -> #REF! | I20: =SUM(C20:G20) -> #REF!
B21: Third Adjustment: Other Increasing Debt | C21: =#REF!+'Civil Debt Exceptions'!C10+'Civil Debt Exceptions'!C30 -> #REF! | D21: =#REF!+'Civil Debt Exceptions'!D10+'Civil Debt Exceptions'!D30 -> #REF! | E21: =#REF!+'Civil Debt Exceptions'!E10+'Civil Debt Exceptions'!E30 -> #REF! | F21: =#REF!+'Civil Debt Exceptions'!F10+'Civil Debt Exceptions'!F30 -> #REF! | G21: =#REF!+'Civil Debt Exceptions'!G10+'Civil Debt Exceptions'!G30 -> #REF! | I21: =SUM(C21:G21) -> #REF!
B22: Third Adjustments:Other Lowering Debt | C22: =#REF!+'Civil Debt Exceptions'!C11+'Civil Debt Exceptions'!C31 -> #REF! | D22: =#REF!+'Civil Debt Exceptions'!D11+'Civil Debt Exceptions'!D31 -> #REF! | E22: =#REF!+'Civil Debt Exceptions'!E11+'Civil Debt Exceptions'!E31 -> #REF! | F22: =#REF!+'Civil Debt Exceptions'!F11+'Civil Debt Exceptions'!F31 -> #REF! | G22: =#REF!+'Civil Debt Exceptions'!G11+'Civil Debt Exceptions'!G31 -> #REF! | I22: =SUM(C22:G22) -> #REF!
B23: Third Adjustments: Writeoff Debt | C23: =#REF!+'Civil Debt Exceptions'!C13+'Civil Debt Exceptions'!C33 -> #REF! | D23: =#REF!+'Civil Debt Exceptions'!D13+'Civil Debt Exceptions'!D33 -> #REF! | E23: =#REF!+'Civil Debt Exceptions'!E13+'Civil Debt Exceptions'!E33 -> #REF! | F23: =#REF!+'Civil Debt Exceptions'!F13+'Civil Debt Exceptions'!F33 -> #REF! | G23: =#REF!+'Civil Debt Exceptions'!G13+'Civil Debt Exceptions'!G33 -> #REF! | I23: =SUM(C23:G23) -> #REF!
B24: Third Adjustments: Writedown Debt | C24: =#REF!+'Civil Debt Exceptions'!C15+'Civil Debt Exceptions'!C35 -> #REF! | D24: =#REF!+'Civil Debt Exceptions'!D15+'Civil Debt Exceptions'!D35 -> #REF! | E24: =#REF!+'Civil Debt Exceptions'!E15+'Civil Debt Exceptions'!E35 -> #REF! | F24: =#REF!+'Civil Debt Exceptions'!F15+'Civil Debt Exceptions'!F35 -> #REF! | G24: =#REF!+'Civil Debt Exceptions'!G15+'Civil Debt Exceptions'!G35 -> #REF! | I24: =SUM(C24:G24) -> #REF!
B25: Third Cash receipts: Debt | C25: =#REF!+'Civil Debt Exceptions'!C17+'Civil Debt Exceptions'!C37 -> #REF! | D25: =#REF!+'Civil Debt Exceptions'!D17+'Civil Debt Exceptions'!D37 -> #REF! | E25: =#REF!+'Civil Debt Exceptions'!E17+'Civil Debt Exceptions'!E37 -> #REF! | F25: =#REF!+'Civil Debt Exceptions'!F17+'Civil Debt Exceptions'!F37 -> #REF! | G25: =#REF!+'Civil Debt Exceptions'!G17+'Civil Debt Exceptions'!G37 -> #REF! | I25: =SUM(C25:G25) -> #REF!
B26: Third Credit memo: Debt | C26: =#REF!+'Civil Debt Exceptions'!C19+'Civil Debt Exceptions'!C39 -> #REF! | D26: =#REF!+'Civil Debt Exceptions'!D19+'Civil Debt Exceptions'!D39 -> #REF! | E26: =#REF!+'Civil Debt Exceptions'!E19+'Civil Debt Exceptions'!E39 -> #REF! | F26: =#REF!+'Civil Debt Exceptions'!F19+'Civil Debt Exceptions'!F39 -> #REF! | G26: =#REF!+'Civil Debt Exceptions'!G19+'Civil Debt Exceptions'!G39 -> #REF! | I26: =SUM(C26:G26) -> #REF!
B28: Balance Principal | C28: =C20-SUM(C21:C26) -> #REF! | D28: =D20-SUM(D21:D26) -> #REF! | E28: =E20-SUM(E21:E26) -> #REF! | F28: =F20-SUM(F21:F26) -> #REF! | G28: =G20-SUM(G21:G26) -> #REF! | I28: =I20-SUM(I21:I26) -> #REF! | K28: =I28+I14 -> #REF! | L28: ='All Debts by Type Summary'!C17 -> #VALUE! | M28: =K28-L28 -> #REF!
B29: CHECKSUM | C29: =#REF!+'Civil Debt Exceptions'!C41+'Civil Debt Exceptions'!C21-C28 -> #REF! | D29: =#REF!+'Civil Debt Exceptions'!D41+'Civil Debt Exceptions'!D21-D28 -> #REF! | E29: =#REF!+'Civil Debt Exceptions'!E41+'Civil Debt Exceptions'!E21-E28 -> #REF! | F29: =#REF!+'Civil Debt Exceptions'!F41+'Civil Debt Exceptions'!F21-F28 -> #REF! | G29: =#REF!+'Civil Debt Exceptions'!G41+'Civil Debt Exceptions'!G21-G28 -> #REF! | I29: =#REF!+'Civil Debt Exceptions'!I41+'Civil Debt Exceptions'!I21-I28 -> #REF!
B31: Late Charges
B33: LAA Charges
B35: Transaction Type | C35: Contributions | D35: Costs | E35: Damages | F35: Revocation | G35: Statutory charge | I35: Total
B36: LAA Adjustment Charges | C36: =#REF! -> #REF! | D36: =#REF! -> #REF! | E36: =#REF! -> #REF! | F36: =#REF! -> #REF! | G36: =#REF! -> #REF! | I36: =SUM(C36:G36) -> #REF!
B37: LAA Adjustments: Writeoff Charge | C37: =#REF! -> #REF! | D37: =#REF! -> #REF! | E37: =#REF! -> #REF! | F37: =#REF! -> #REF! | G37: =#REF! -> #REF! | I37: =SUM(C37:G37) -> #REF!
B38: LAA Adjustments: Writedown Charge | C38: =#REF! -> #REF! | D38: =#REF! -> #REF! | E38: =#REF! -> #REF! | F38: =#REF! -> #REF! | G38: =#REF! -> #REF! | I38: =SUM(C38:G38) -> #REF!
B39: LAA Cash receipts: Charge | C39: =#REF! -> #REF! | D39: =#REF! -> #REF! | E39: =#REF! -> #REF! | F39: =#REF! -> #REF! | G39: =#REF! -> #REF! | I39: =SUM(C39:G39) -> #REF!
B40: LAA Credit memo: Late Charge | C40: =#REF! -> #REF! | D40: =#REF! -> #REF! | E40: =#REF! -> #REF! | F40: =#REF! -> #REF! | G40: =#REF! -> #REF! | I40: =SUM(C40:G40) -> #REF!
B42: Balance Charges | C42: =-C36-SUM(C37:C40) -> #REF! | D42: =-D36-SUM(D37:D40) -> #REF! | E42: =-E36-SUM(E37:E40) -> #REF! | F42: =-F36-SUM(F37:F40) -> #REF! | G42: =-G36-SUM(G37:G40) -> #REF! | I42: =-I36-SUM(I37:I40) -> #REF!
B43: CHECKSUM | C43: =#REF!-C42 -> #REF! | D43: =#REF!-D42 -> #REF! | E43: =#REF!-E42 -> #REF! | F43: =#REF!-F42 -> #REF! | G43: =#REF!-G42 -> #REF! | I43: =#REF!-I42 -> #REF!
B45: Third Charges
B47: Transaction Type | C47: Contributions | D47: Costs | E47: Damages | F47: Revocation | G47: Statutory charge | I47: Total
B48: Third Adjustment Charges | C48: ='Civil Debt Exceptions'!C9+'Civil Debt Exceptions'!C29 -> #REF! | D48: ='Civil Debt Exceptions'!D9+'Civil Debt Exceptions'!D29 -> #REF! | E48: ='Civil Debt Exceptions'!E9+'Civil Debt Exceptions'!E29 -> #REF! | F48: ='Civil Debt Exceptions'!F9+'Civil Debt Exceptions'!F29 -> #REF! | G48: ='Civil Debt Exceptions'!G9+'Civil Debt Exceptions'!G29 -> #REF! | I48: =SUM(C48:G48) -> #REF!
B49: Third Adjustments: Writeoff Charge | C49: ='Civil Debt Exceptions'!C12+'Civil Debt Exceptions'!C32 -> #REF! | D49: ='Civil Debt Exceptions'!D12+'Civil Debt Exceptions'!D32 -> #REF! | E49: ='Civil Debt Exceptions'!E12+'Civil Debt Exceptions'!E32 -> #REF! | F49: ='Civil Debt Exceptions'!F12+'Civil Debt Exceptions'!F32 -> #REF! | G49: ='Civil Debt Exceptions'!G12+'Civil Debt Exceptions'!G32 -> #REF! | I49: =SUM(C49:G49) -> #REF!
B50: Third Adjustments: Writedown Charge | C50: =+'Civil Debt Exceptions'!C14+'Civil Debt Exceptions'!C34 -> #REF! | D50: =+'Civil Debt Exceptions'!D14+'Civil Debt Exceptions'!D34 -> #REF! | E50: =+'Civil Debt Exceptions'!E14+'Civil Debt Exceptions'!E34 -> #REF! | F50: =+'Civil Debt Exceptions'!F14+'Civil Debt Exceptions'!F34 -> #REF! | G50: =+'Civil Debt Exceptions'!G14+'Civil Debt Exceptions'!G34 -> #REF! | I50: =SUM(C50:G50) -> #REF!
B51: Third Cash receipts: Charge | C51: =+'Civil Debt Exceptions'!C16+'Civil Debt Exceptions'!C36 -> #REF! | D51: =+'Civil Debt Exceptions'!D16+'Civil Debt Exceptions'!D36 -> #REF! | E51: =+'Civil Debt Exceptions'!E16+'Civil Debt Exceptions'!E36 -> #REF! | F51: =+'Civil Debt Exceptions'!F16+'Civil Debt Exceptions'!F36 -> #REF! | G51: =+'Civil Debt Exceptions'!G16+'Civil Debt Exceptions'!G36 -> #REF! | I51: =SUM(C51:G51) -> #REF!
B52: Third Credit memo: Late Charge | C52: =+'Civil Debt Exceptions'!C18+'Civil Debt Exceptions'!C38 -> #REF! | D52: =+'Civil Debt Exceptions'!D18+'Civil Debt Exceptions'!D38 -> #REF! | E52: =+'Civil Debt Exceptions'!E18+'Civil Debt Exceptions'!E38 -> #REF! | F52: =+'Civil Debt Exceptions'!F18+'Civil Debt Exceptions'!F38 -> #REF! | G52: =+'Civil Debt Exceptions'!G18+'Civil Debt Exceptions'!G38 -> #REF! | I52: =SUM(C52:G52) -> #REF!
...

Sheet All Debts by Type Summary
B1: All CCMS debts by scheme
B3: Transaction Type | C3: Civil | D3: Crime Higher | E3: Other | F3: Provider | G3: Staff Debt | I3: Total | K3: Contributions | L3: Costs | M3: Damages | N3: Revocation | O3: Statutory charge | Q3: Total Civil
B4: Debt invoices | C4: =SUMIF([2]CCMS_DEBT_SUMMARY_C_EXP!$A:$A,$C$3,[2]CCMS_DEBT_SUMMARY_C_EXP!$G:$G) -> #VALUE! | D4: =SUMIF([2]CCMS_DEBT_SUMMARY_C_EXP!$A:$A,$D$3,[2]CCMS_DEBT_SUMMARY_C_EXP!$G:$G) -> #VALUE! | E4: =SUMIF([2]CCMS_DEBT_SUMMARY_C_EXP!$A:$A,$E$3,[2]CCMS_DEBT_SUMMARY_C_EXP!$G:$G) -> #VALUE! | F4: =SUMIF([2]CCMS_DEBT_SUMMARY_C_EXP!$A:$A,$F$3,[2]CCMS_DEBT_SUMMARY_C_EXP!$G:$G) -> #VALUE! | G4: =SUMIF([2]CCMS_DEBT_SUMMARY_C_EXP!$A:$A,$G$3,[2]CCMS_DEBT_SUMMARY_C_EXP!$G:$G) -> #VALUE! | I4: =SUM(C4:H4) -> #VALUE! | K4: =SUMIF([2]CCMS_DEBT_SUMMARY_C_EXP!$C:$C,K$3,[2]CCMS_DEBT_SUMMARY_C_EXP!$G:$G) -> #VALUE! | L4: =SUMIF([2]CCMS_DEBT_SUMMARY_C_EXP!$C:$C,L$3,[2]CCMS_DEBT_SUMMARY_C_EXP!$G:$G) -> #VALUE! | M4: =SUMIF([2]CCMS_DEBT_SUMMARY_C_EXP!$C:$C,M$3,[2]CCMS_DEBT_SUMMARY_C_EXP!$G:$G) -> #VALUE! | N4: =SUMIF([2]CCMS_DEBT_SUMMARY_C_EXP!$C:$C,N$3,[2]CCMS_DEBT_SUMMARY_C_EXP!$G:$G) -> #VALUE! | O4: =SUMIF([2]CCMS_DEBT_SUMMARY_C_EXP!$C:$C,O$3,[2]CCMS_DEBT_SUMMARY_C_EXP!$G:$G) -> #VALUE! | Q4: =SUM(K4:P4) -> #VALUE!
B5: Adjustment Charges | C5: =SUMIF([2]CCMS_DEBT_SUMMARY_C_EXP!$A:$A,$C$3,[2]CCMS_DEBT_SUMMARY_C_EXP!$N:$N)*-1 -> #VALUE! | D5: =SUMIF([2]CCMS_DEBT_SUMMARY_C_EXP!$A:$A,$D$3,[2]CCMS_DEBT_SUMMARY_C_EXP!$N:$N)*-1 -> #VALUE! | E5: =SUMIF([2]CCMS_DEBT_SUMMARY_C_EXP!$A:$A,$E$3,[2]CCMS_DEBT_SUMMARY_C_EXP!$N:$N)*-1 -> #VALUE! | F5: =SUMIF([2]CCMS_DEBT_SUMMARY_C_EXP!$A:$A,$F$3,[2]CCMS_DEBT_SUMMARY_C_EXP!$N:$N)*-1 -> #VALUE! | G5: =SUMIF([2]CCMS_DEBT_SUMMARY_C_EXP!$A:$A,$G$3,[2]CCMS_DEBT_SUMMARY_C_EXP!$N:$N)*-1 -> #VALUE! | I5: =SUM(C5:H5) -> #VALUE! | K5: =SUMIF([2]CCMS_DEBT_SUMMARY_C_EXP!$C:$C,K$3,[2]CCMS_DEBT_SUMMARY_C_EXP!$N:$N)*-1 -> #VALUE! | L5: =SUMIF([2]CCMS_DEBT_SUMMARY_C_EXP!$C:$C,L$3,[2]CCMS_DEBT_SUMMARY_C_EXP!$N:$N)*-1 -> #VALUE! | M5: =SUMIF([2]CCMS_DEBT_SUMMARY_C_EXP!$C:$C,M$3,[2]CCMS_DEBT_SUMMARY_C_EXP!$N:$N)*-1 -> #VALUE! | N5: =SUMIF([2]CCMS_DEBT_SUMMARY_C_EXP!$C:$C,N$3,[2]CCMS_DEBT_SUMMARY_C_EXP!$N:$N)*-1 -> #VALUE! | O5: =SUMIF([2]CCMS_DEBT_SUMMARY_C_EXP!$C:$C,O$3,[2]CCMS_DEBT_SUMMARY_C_EXP!$N:$N)*-1 -> #VALUE! | Q5: =SUM(K5:P5) -> #VALUE!
B6: Adjustment: Other Increasing debt | C6: =SUMIF([2]CCMS_DEBT_SUMMARY_C_EXP!$A:$A,C$3,[2]CCMS_DEBT_SUMMARY_C_EXP!$L:$L)*-1 -> #VALUE! | D6: =SUMIF([2]CCMS_DEBT_SUMMARY_C_EXP!$A:$A,D$3,[2]CCMS_DEBT_SUMMARY_C_EXP!$L:$KL)*-1 -> #VALUE! | E6: =SUMIF([2]CCMS_DEBT_SUMMARY_C_EXP!$A:$A,E$3,[2]CCMS_DEBT_SUMMARY_C_EXP!$L:$KL)*-1 -> #VALUE! | F6: =SUMIF([2]CCMS_DEBT_SUMMARY_C_EXP!$A:$A,F$3,[2]CCMS_DEBT_SUMMARY_C_EXP!$L:$KL)*-1 -> #VALUE! | G6: =SUMIF([2]CCMS_DEBT_SUMMARY_C_EXP!$A:$A,G$3,[2]CCMS_DEBT_SUMMARY_C_EXP!$L:$KL)*-1 -> #VALUE! | I6: =SUM(C6:H6) -> #VALUE! | K6: =SUMIF([2]CCMS_DEBT_SUMMARY_C_EXP!$C:$C,K$3,[2]CCMS_DEBT_SUMMARY_C_EXP!$L:$L)*-1 -> #VALUE! | L6: =SUMIF([2]CCMS_DEBT_SUMMARY_C_EXP!$C:$C,L$3,[2]CCMS_DEBT_SUMMARY_C_EXP!$L:$L)*-1 -> #VALUE! | M6: =SUMIF([2]CCMS_DEBT_SUMMARY_C_EXP!$C:$C,M$3,[2]CCMS_DEBT_SUMMARY_C_EXP!$L:$L)*-1 -> #VALUE! | N6: =SUMIF([2]CCMS_DEBT_SUMMARY_C_EXP!$C:$C,N$3,[2]CCMS_DEBT_SUMMARY_C_EXP!$L:$L)*-1 -> #VALUE! | O6: =SUMIF([2]CCMS_DEBT_SUMMARY_C_EXP!$C:$C,O$3,[2]CCMS_DEBT_SUMMARY_C_EXP!$L:$L)*-1 -> #VALUE! | Q6: =SUM(K6:P6) -> #VALUE!
B7: Adjustments: Other Lowering debt | C7: =SUMIF([2]CCMS_DEBT_SUMMARY_C_EXP!$A:$A,C$3,[2]CCMS_DEBT_SUMMARY_C_EXP!$M:$M)*-1 -> #VALUE! | D7: =SUMIF([2]CCMS_DEBT_SUMMARY_C_EXP!$A:$A,D$3,[2]CCMS_DEBT_SUMMARY_C_EXP!$M:$M)*-1 -> #VALUE! | E7: =SUMIF([2]CCMS_DEBT_SUMMARY_C_EXP!$A:$A,E$3,[2]CCMS_DEBT_SUMMARY_C_EXP!$M:$M)*-1 -> #VALUE! | F7: =SUMIF([2]CCMS_DEBT_SUMMARY_C_EXP!$A:$A,F$3,[2]CCMS_DEBT_SUMMARY_C_EXP!$M:$M)*-1 -> #VALUE! | G7: =SUMIF([2]CCMS_DEBT_SUMMARY_C_EXP!$A:$A,G$3,[2]CCMS_DEBT_SUMMARY_C_EXP!$M:$M)*-1 -> #VALUE! | I7: =SUM(C7:H7) -> #VALUE! | K7: =SUMIF([2]CCMS_DEBT_SUMMARY_C_EXP!$C:$C,K$3,[2]CCMS_DEBT_SUMMARY_C_EXP!$M:$M)*-1 -> #VALUE! | L7: =SUMIF([2]CCMS_DEBT_SUMMARY_C_EXP!$C:$C,L$3,[2]CCMS_DEBT_SUMMARY_C_EXP!$M:$M)*-1 -> #VALUE! | M7: =SUMIF([2]CCMS_DEBT_SUMMARY_C_EXP!$C:$C,M$3,[2]CCMS_DEBT_SUMMARY_C_EXP!$M:$M)*-1 -> #VALUE! | N7: =SUMIF([2]CCMS_DEBT_SUMMARY_C_EXP!$C:$C,N$3,[2]CCMS_DEBT_SUMMARY_C_EXP!$M:$M)*-1 -> #VALUE! | O7: =SUMIF([2]CCMS_DEBT_SUMMARY_C_EXP!$C:$C,O$3,[2]CCMS_DEBT_SUMMARY_C_EXP!$M:$M)*-1 -> #VALUE! | Q7: =SUM(K7:P7) -> #VALUE!
B8: Adjustments: Writeoff Charge | C8: =SUMIF([2]CCMS_DEBT_SUMMARY_C_EXP!$A:$A,$C$3,[2]CCMS_DEBT_SUMMARY_C_EXP!$R:$R)*-1 -> #VALUE! | D8: =SUMIF([2]CCMS_DEBT_SUMMARY_C_EXP!$A:$A,$D$3,[2]CCMS_DEBT_SUMMARY_C_EXP!$R:$R)*-1 -> #VALUE! | E8: =SUMIF([2]CCMS_DEBT_SUMMARY_C_EXP!$A:$A,$E$3,[2]CCMS_DEBT_SUMMARY_C_EXP!$R:$R)*-1 -> #VALUE! | F8: =SUMIF([2]CCMS_DEBT_SUMMARY_C_EXP!$A:$A,$F$3,[2]CCMS_DEBT_SUMMARY_C_EXP!$R:$R)*-1 -> #VALUE! | G8: =SUMIF([2]CCMS_DEBT_SUMMARY_C_EXP!$A:$A,$G$3,[2]CCMS_DEBT_SUMMARY_C_EXP!$R:$R)*-1 -> #VALUE! | I8: =SUM(C8:H8) -> #VALUE! | K8: =SUMIF([2]CCMS_DEBT_SUMMARY_C_EXP!$C:$C,K$3,[2]CCMS_DEBT_SUMMARY_C_EXP!$R:$R)*-1 -> #VALUE! | L8: =SUMIF([2]CCMS_DEBT_SUMMARY_C_EXP!$C:$C,L$3,[2]CCMS_DEBT_SUMMARY_C_EXP!$R:$R)*-1 -> #VALUE! | M8: =SUMIF([2]CCMS_DEBT_SUMMARY_C_EXP!$C:$C,M$3,[2]CCMS_DEBT_SUMMARY_C_EXP!$R:$R)*-1 -> #VALUE! | N8: =SUMIF([2]CCMS_DEBT_SUMMARY_C_EXP!$C:$C,N$3,[2]CCMS_DEBT_SUMMARY_C_EXP!$R:$R)*-1 -> #VALUE! | O8: =SUMIF([2]CCMS_DEBT_SUMMARY_C_EXP!$C:$C,O$3,[2]CCMS_DEBT_SUMMARY_C_EXP!$R:$R)*-1 -> #VALUE! | Q8: =SUM(K8:P8) -> #VALUE!
B9: Adjustments: Writeoff Debt | C9: =SUMIF([2]CCMS_DEBT_SUMMARY_C_EXP!$A:$A,$C$3,[2]CCMS_DEBT_SUMMARY_C_EXP!$Q:$Q)*-1 -> #VALUE! | D9: =SUMIF([2]CCMS_DEBT_SUMMARY_C_EXP!$A:$A,$D$3,[2]CCMS_DEBT_SUMMARY_C_EXP!$Q:$Q)*-1 -> #VALUE! | E9: =SUMIF([2]CCMS_DEBT_SUMMARY_C_EXP!$A:$A,$E$3,[2]CCMS_DEBT_SUMMARY_C_EXP!$Q:$Q)*-1 -> #VALUE! | F9: =SUMIF([2]CCMS_DEBT_SUMMARY_C_EXP!$A:$A,$F$3,[2]CCMS_DEBT_SUMMARY_C_EXP!$Q:$Q)*-1 -> #VALUE! | G9: =SUMIF([2]CCMS_DEBT_SUMMARY_C_EXP!$A:$A,$G$3,[2]CCMS_DEBT_SUMMARY_C_EXP!$Q:$Q)*-1 -> #VALUE! | I9: =SUM(C9:H9) -> #VALUE! | K9: =SUMIF([2]CCMS_DEBT_SUMMARY_C_EXP!$C:$C,K$3,[2]CCMS_DEBT_SUMMARY_C_EXP!$Q:$Q)*-1 -> #VALUE! | L9: =SUMIF([2]CCMS_DEBT_SUMMARY_C_EXP!$C:$C,L$3,[2]CCMS_DEBT_SUMMARY_C_EXP!$Q:$Q)*-1 -> #VALUE! | M9: =SUMIF([2]CCMS_DEBT_SUMMARY_C_EXP!$C:$C,M$3,[2]CCMS_DEBT_SUMMARY_C_EXP!$Q:$Q)*-1 -> #VALUE! | N9: =SUMIF([2]CCMS_DEBT_SUMMARY_C_EXP!$C:$C,N$3,[2]CCMS_DEBT_SUMMARY_C_EXP!$Q:$Q)*-1 -> #VALUE! | O9: =SUMIF([2]CCMS_DEBT_SUMMARY_C_EXP!$C:$C,O$3,[2]CCMS_DEBT_SUMMARY_C_EXP!$Q:$Q)*-1 -> #VALUE! | Q9: =SUM(K9:P9) -> #VALUE!
B10: Adjustments: Writedown Charge | C10: =SUMIF([2]CCMS_DEBT_SUMMARY_C_EXP!$A:$A,$C$3,[2]CCMS_DEBT_SUMMARY_C_EXP!$P:$P)*-1 -> #VALUE! | D10: =SUMIF([2]CCMS_DEBT_SUMMARY_C_EXP!$A:$A,$D$3,[2]CCMS_DEBT_SUMMARY_C_EXP!$P:$P)*-1 -> #VALUE! | E10: =SUMIF([2]CCMS_DEBT_SUMMARY_C_EXP!$A:$A,$E$3,[2]CCMS_DEBT_SUMMARY_C_EXP!$P:$P)*-1 -> #VALUE! | F10: =SUMIF([2]CCMS_DEBT_SUMMARY_C_EXP!$A:$A,$F$3,[2]CCMS_DEBT_SUMMARY_C_EXP!$P:$P)*-1 -> #VALUE! | G10: =SUMIF([2]CCMS_DEBT_SUMMARY_C_EXP!$A:$A,$G$3,[2]CCMS_DEBT_SUMMARY_C_EXP!$P:$P)*-1 -> #VALUE! | I10: =SUM(C10:H10) -> #VALUE! | K10: =SUMIF([2]CCMS_DEBT_SUMMARY_C_EXP!$C:$C,K$3,[2]CCMS_DEBT_SUMMARY_C_EXP!$P:$P)*-1 -> #VALUE! | L10: =SUMIF([2]CCMS_DEBT_SUMMARY_C_EXP!$C:$C,L$3,[2]CCMS_DEBT_SUMMARY_C_EXP!$P:$P)*-1 -> #VALUE! | M10: =SUMIF([2]CCMS_DEBT_SUMMARY_C_EXP!$C:$C,M$3,[2]CCMS_DEBT_SUMMARY_C_EXP!$P:$P)*-1 -> #VALUE! | N10: =SUMIF([2]CCMS_DEBT_SUMMARY_C_EXP!$C:$C,N$3,[2]CCMS_DEBT_SUMMARY_C_EXP!$P:$P)*-1 -> #VALUE! | O10: =SUMIF([2]CCMS_DEBT_SUMMARY_C_EXP!$C:$C,O$3,[2]CCMS_DEBT_SUMMARY_C_EXP!$P:$P)*-1 -> #VALUE! | Q10: =SUM(K10:P10) -> #VALUE!
B11: Adjustments: Writedown Debt | C11: =SUMIF([2]CCMS_DEBT_SUMMARY_C_EXP!$A:$A,$C$3,[2]CCMS_DEBT_SUMMARY_C_EXP!$O:$O)*-1 -> #VALUE! | D11: =SUMIF([2]CCMS_DEBT_SUMMARY_C_EXP!$A:$A,$D$3,[2]CCMS_DEBT_SUMMARY_C_EXP!$O:$O)*-1 -> #VALUE! | E11: =SUMIF([2]CCMS_DEBT_SUMMARY_C_EXP!$A:$A,$E$3,[2]CCMS_DEBT_SUMMARY_C_EXP!$O:$O)*-1 -> #VALUE! | F11: =SUMIF([2]CCMS_DEBT_SUMMARY_C_EXP!$A:$A,$F$3,[2]CCMS_DEBT_SUMMARY_C_EXP!$O:$O)*-1 -> #VALUE! | G11: =SUMIF([2]CCMS_DEBT_SUMMARY_C_EXP!$A:$A,$G$3,[2]CCMS_DEBT_SUMMARY_C_EXP!$O:$O)*-1 -> #VALUE! | I11: =SUM(C11:H11) -> #VALUE! | K11: =SUMIF([2]CCMS_DEBT_SUMMARY_C_EXP!$C:$C,K$3,[2]CCMS_DEBT_SUMMARY_C_EXP!$O:$O)*-1 -> #VALUE! | L11: =SUMIF([2]CCMS_DEBT_SUMMARY_C_EXP!$C:$C,L$3,[2]CCMS_DEBT_SUMMARY_C_EXP!$O:$O)*-1 -> #VALUE! | M11: =SUMIF([2]CCMS_DEBT_SUMMARY_C_EXP!$C:$C,M$3,[2]CCMS_DEBT_SUMMARY_C_EXP!$O:$O)*-1 -> #VALUE! | N11: =SUMIF([2]CCMS_DEBT_SUMMARY_C_EXP!$C:$C,N$3,[2]CCMS_DEBT_SUMMARY_C_EXP!$O:$O)*-1 -> #VALUE! | O11: =SUMIF([2]CCMS_DEBT_SUMMARY_C_EXP!$C:$C,O$3,[2]CCMS_DEBT_SUMMARY_C_EXP!$O:$O)*-1 -> #VALUE! | Q11: =SUM(K11:P11) -> #VALUE!
B12: Cash receipts: Charge | C12: =SUMIF([2]CCMS_DEBT_SUMMARY_C_EXP!$A:$A,$C$3,[2]CCMS_DEBT_SUMMARY_C_EXP!$T:$T) -> #VALUE! | D12: =SUMIF([2]CCMS_DEBT_SUMMARY_C_EXP!$A:$A,$D$3,[2]CCMS_DEBT_SUMMARY_C_EXP!$T:$T) -> #VALUE! | E12: =SUMIF([2]CCMS_DEBT_SUMMARY_C_EXP!$A:$A,$E$3,[2]CCMS_DEBT_SUMMARY_C_EXP!$T:$T) -> #VALUE! | F12: =SUMIF([2]CCMS_DEBT_SUMMARY_C_EXP!$A:$A,$F$3,[2]CCMS_DEBT_SUMMARY_C_EXP!$T:$T) -> #VALUE! | G12: =SUMIF([2]CCMS_DEBT_SUMMARY_C_EXP!$A:$A,$G$3,[2]CCMS_DEBT_SUMMARY_C_EXP!$T:$T) -> #VALUE! | I12: =SUM(C12:H12) -> #VALUE! | K12: =SUMIF([2]CCMS_DEBT_SUMMARY_C_EXP!$C:$C,K$3,[2]CCMS_DEBT_SUMMARY_C_EXP!$T:$T) -> #VALUE! | L12: =SUMIF([2]CCMS_DEBT_SUMMARY_C_EXP!$C:$C,L$3,[2]CCMS_DEBT_SUMMARY_C_EXP!$T:$T) -> #VALUE! | M12: =SUMIF([2]CCMS_DEBT_SUMMARY_C_EXP!$C:$C,M$3,[2]CCMS_DEBT_SUMMARY_C_EXP!$T:$T) -> #VALUE! | N12: =SUMIF([2]CCMS_DEBT_SUMMARY_C_EXP!$C:$C,N$3,[2]CCMS_DEBT_SUMMARY_C_EXP!$T:$T) -> #VALUE! | O12: =SUMIF([2]CCMS_DEBT_SUMMARY_C_EXP!$C:$C,O$3,[2]CCMS_DEBT_SUMMARY_C_EXP!$T:$T) -> #VALUE! | Q12: =SUM(K12:P12) -> #VALUE!
B13: Cash receipts: Debt | C13: =SUMIF([2]CCMS_DEBT_SUMMARY_C_EXP!$A:$A,$C$3,[2]CCMS_DEBT_SUMMARY_C_EXP!$S:$S) -> #VALUE! | D13: =SUMIF([2]CCMS_DEBT_SUMMARY_C_EXP!$A:$A,$D$3,[2]CCMS_DEBT_SUMMARY_C_EXP!$S:$S) -> #VALUE! | E13: =SUMIF([2]CCMS_DEBT_SUMMARY_C_EXP!$A:$A,$E$3,[2]CCMS_DEBT_SUMMARY_C_EXP!$S:$S) -> #VALUE! | F13: =SUMIF([2]CCMS_DEBT_SUMMARY_C_EXP!$A:$A,$F$3,[2]CCMS_DEBT_SUMMARY_C_EXP!$S:$S) -> #VALUE! | G13: =SUMIF([2]CCMS_DEBT_SUMMARY_C_EXP!$A:$A,$G$3,[2]CCMS_DEBT_SUMMARY_C_EXP!$S:$S) -> #VALUE! | I13: =SUM(C13:H13) -> #VALUE! | K13: =SUMIF([2]CCMS_DEBT_SUMMARY_C_EXP!$C:$C,K$3,[2]CCMS_DEBT_SUMMARY_C_EXP!$S:$S) -> #VALUE! | L13: =SUMIF([2]CCMS_DEBT_SUMMARY_C_EXP!$C:$C,L$3,[2]CCMS_DEBT_SUMMARY_C_EXP!$S:$S) -> #VALUE! | M13: =SUMIF([2]CCMS_DEBT_SUMMARY_C_EXP!$C:$C,M$3,[2]CCMS_DEBT_SUMMARY_C_EXP!$S:$S) -> #VALUE! | N13: =SUMIF([2]CCMS_DEBT_SUMMARY_C_EXP!$C:$C,N$3,[2]CCMS_DEBT_SUMMARY_C_EXP!$S:$S) -> #VALUE! | O13: =SUMIF([2]CCMS_DEBT_SUMMARY_C_EXP!$C:$C,O$3,[2]CCMS_DEBT_SUMMARY_C_EXP!$S:$S) -> #VALUE! | Q13: =SUM(K13:P13) -> #VALUE!
B14: Credit memo: Late Charge | C14: =SUMIF([2]CCMS_DEBT_SUMMARY_C_EXP!$A:$A,C$3,[2]CCMS_DEBT_SUMMARY_C_EXP!$I:$I) -> #VALUE! | D14: =SUMIF([2]CCMS_DEBT_SUMMARY_C_EXP!$A:$A,$D$3,[2]CCMS_DEBT_SUMMARY_C_EXP!$I:$I) -> #VALUE! | E14: =SUMIF([2]CCMS_DEBT_SUMMARY_C_EXP!$A:$A,$E$3,[2]CCMS_DEBT_SUMMARY_C_EXP!$I:$I) -> #VALUE! | F14: =SUMIF([2]CCMS_DEBT_SUMMARY_C_EXP!$A:$A,$F$3,[2]CCMS_DEBT_SUMMARY_C_EXP!$I:$I) -> #VALUE! | G14: =SUMIF([2]CCMS_DEBT_SUMMARY_C_EXP!$A:$A,$G$3,[2]CCMS_DEBT_SUMMARY_C_EXP!$I:$I) -> #VALUE! | I14: =SUM(C14:H14) -> #VALUE! | K14: =SUMIF([2]CCMS_DEBT_SUMMARY_C_EXP!$C:$C,K$3,[2]CCMS_DEBT_SUMMARY_C_EXP!$I:$I) -> #VALUE! | L14: =SUMIF([2]CCMS_DEBT_SUMMARY_C_EXP!$C:$C,L$3,[2]CCMS_DEBT_SUMMARY_C_EXP!$I:$I) -> #VALUE! | M14: =SUMIF([2]CCMS_DEBT_SUMMARY_C_EXP!$C:$C,M$3,[2]CCMS_DEBT_SUMMARY_C_EXP!$I:$I) -> #VALUE! | N14: =SUMIF([2]CCMS_DEBT_SUMMARY_C_EXP!$C:$C,N$3,[2]CCMS_DEBT_SUMMARY_C_EXP!$I:$I) -> #VALUE! | O14: =SUMIF([2]CCMS_DEBT_SUMMARY_C_EXP!$C:$C,O$3,[2]CCMS_DEBT_SUMMARY_C_EXP!$I:$I) -> #VALUE! | Q14: =SUM(K14:P14) -> #VALUE!
B15: Credit memo: Debt | C15: =SUMIF([2]CCMS_DEBT_SUMMARY_C_EXP!$A:$A,$C$3,[2]CCMS_DEBT_SUMMARY_C_EXP!$H:$H) -> #VALUE! | D15: =SUMIF([2]CCMS_DEBT_SUMMARY_C_EXP!$A:$A,$D$3,[2]CCMS_DEBT_SUMMARY_C_EXP!$H:$H) -> #VALUE! | E15: =SUMIF([2]CCMS_DEBT_SUMMARY_C_EXP!$A:$A,$E$3,[2]CCMS_DEBT_SUMMARY_C_EXP!$H:$H) -> #VALUE! | F15: =SUMIF([2]CCMS_DEBT_SUMMARY_C_EXP!$A:$A,$F$3,[2]CCMS_DEBT_SUMMARY_C_EXP!$H:$H) -> #VALUE! | G15: =SUMIF([2]CCMS_DEBT_SUMMARY_C_EXP!$A:$A,$G$3,[2]CCMS_DEBT_SUMMARY_C_EXP!$H:$H) -> #VALUE! | I15: =SUM(C15:H15) -> #VALUE! | K15: =SUMIF([2]CCMS_DEBT_SUMMARY_C_EXP!$C:$C,K$3,[2]CCMS_DEBT_SUMMARY_C_EXP!$H:$H) -> #VALUE! | L15: =SUMIF([2]CCMS_DEBT_SUMMARY_C_EXP!$C:$C,L$3,[2]CCMS_DEBT_SUMMARY_C_EXP!$H:$H) -> #VALUE! | M15: =SUMIF([2]CCMS_DEBT_SUMMARY_C_EXP!$C:$C,M$3,[2]CCMS_DEBT_SUMMARY_C_EXP!$H:$H) -> #VALUE! | N15: =SUMIF([2]CCMS_DEBT_SUMMARY_C_EXP!$C:$C,N$3,[2]CCMS_DEBT_SUMMARY_C_EXP!$H:$H) -> #VALUE! | O15: =SUMIF([2]CCMS_DEBT_SUMMARY_C_EXP!$C:$C,O$3,[2]CCMS_DEBT_SUMMARY_C_EXP!$H:$H) -> #VALUE! | Q15: =SUM(K15:P15) -> #VALUE!
B17: Balance Principal | C17: =C4-C6-C7-C9-C11-C13-C15 -> #VALUE! | D17: =D4-D6-D7-D9-D11-D13-D15 -> #VALUE! | E17: =E4-E6-E7-E9-E11-E13-E15 -> #VALUE! | F17: =F4-F6-F7-F9-F11-F13-F15 -> #VALUE! | G17: =G4-G6-G7-G9-G11-G13-G15 -> #VALUE! | I17: =I4-I6-I7-I9-I11-I13-I15 -> #VALUE! | K17: =K4-K6-K7-K9-K11-K13-K15 -> #VALUE! | L17: =L4-L6-L7-L9-L11-L13-L15 -> #VALUE! | M17: =M4-M6-M7-M9-M11-M13-M15 -> #VALUE! | N17: =N4-N6-N7-N9-N11-N13-N15 -> #VALUE! | O17: =O4-O6-O7-O9-O11-O13-O15 -> #VALUE! | Q17: =SUM(K17:P17) -> #VALUE!
B19: Balance Charges | C19: =-C5-C8-C10-C12-C14 -> #VALUE! | D19: =-D5-D8-D10-D12-D14 -> #VALUE! | E19: =-E5-E8-E10-E12-E14 -> #VALUE! | F19: =-F5-F8-F10-F12-F14 -> #VALUE! | G19: =-G5-G8-G10-G12-G14 -> #VALUE! | I19: =-I5-I8-I10-I12-I14 -> #VALUE! | K19: =-K5-K8-K10-K12-K14 -> #VALUE! | L19: =-L5-L8-L10-L12-L14 -> #VALUE! | M19: =-M5-M8-M10-M12-M14 -> #VALUE! | N19: =-N5-N8-N10-N12-N14 -> #VALUE! | O19: =-O5-O8-O10-O12-O14 -> #VALUE! | Q19: =SUM(K19:P19) -> #VALUE!
B21: Movement Summaries
B23: Principal
B24: Transaction Type | C24: Civil | D24: Crime Higher | E24: Other | F24: Provider | G24: Staff Debt | I24: Total
B25: 1) Debt invoices | C25: =C4 -> #VALUE! | D25: =D4 -> #VALUE! | E25: =E4 -> #VALUE! | F25: =F4 -> #VALUE! | G25: =G4 -> #VALUE! | I25: =I4 -> #VALUE!
B26: 2) Adjustment: Other Increasing Debt | C26: =C6 -> #VALUE! | D26: =D6 -> #VALUE! | E26: =E6 -> #VALUE! | F26: =F6 -> #VALUE! | G26: =G6 -> #VALUE! | I26: =I6 -> #VALUE!
B27: 3) Adjustments: Other Lowering Debt | C27: =C7 -> #VALUE! | D27: =D7 -> #VALUE! | E27: =E7 -> #VALUE! | F27: =F7 -> #VALUE! | G27: =G7 -> #VALUE! | I27: =I7 -> #VALUE!
B28: 4) Adjustments: Writeoff Debt | C28: =C9 -> #VALUE! | D28: =D9 -> #VALUE! | E28: =E9 -> #VALUE! | F28: =F9 -> #VALUE! | G28: =G9 -> #VALUE! | I28: =I9 -> #VALUE!
B29: 5) Adjustments: Writedown Debt | C29: =C11 -> #VALUE! | D29: =D11 -> #VALUE! | E29: =E11 -> #VALUE! | F29: =F11 -> #VALUE! | G29: =G11 -> #VALUE! | I29: =I11 -> #VALUE!
B30: 6) Cash receipts: Debt | C30: =C13 -> #VALUE! | D30: =D13 -> #VALUE! | E30: =E13 -> #VALUE! | F30: =F13 -> #VALUE! | G30: =G13 -> #VALUE! | I30: =I13 -> #VALUE!
B31: 7) Credit memo: Debt | C31: =C15 -> #VALUE! | D31: =D15 -> #VALUE! | E31: =E15 -> #VALUE! | F31: =F15 -> #VALUE! | G31: =G15 -> #VALUE! | I31: =I15 -> #VALUE!
B32: Total | C32: =C25-SUM(C26:C31) -> #VALUE! | D32: =D25-SUM(D26:D31) -> #VALUE! | E32: =E25-SUM(E26:E31) -> #VALUE! | F32: =F25-SUM(F26:F31) -> #VALUE! | G32: =G25-SUM(G26:G31) -> #VALUE! | I32: =I25-SUM(I26:I31) -> #VALUE!
B33: CHECKSUM | C33: =C32-C17 -> #VALUE! | D33: =D32-D17 -> #VALUE! | E33: =E32-E17 -> #VALUE! | F33: =F32-F17 -> #VALUE! | G33: =G32-G17 -> #VALUE! | I33: =I32-I17 -> #VALUE!
B35: Late Charges
B36: Transaction Type | C36: Civil | D36: Crime Higher | E36: Other | F36: Provider | G36: Staff Debt | I36: Total
B37: 8) Adjustment Charges | C37: =C5 -> #VALUE! | D37: =D5 -> #VALUE! | E37: =E5 -> #VALUE! | F37: =F5 -> #VALUE! | G37: =G5 -> #VALUE! | I37: =I5 -> #VALUE!
B38: 9) Adjustments: Writeoff Charge | C38: =C8 -> #VALUE! | D38: =D8 -> #VALUE! | E38: =E8 -> #VALUE! | F38: =F8 -> #VALUE! | G38: =G8 -> #VALUE! | I38: =I8 -> #VALUE!
B39: 10) Adjustments: Writedown Charge | C39: =C10 -> #VALUE! | D39: =D10 -> #VALUE! | E39: =E10 -> #VALUE! | F39: =F10 -> #VALUE! | G39: =G10 -> #VALUE! | I39: =I10 -> #VALUE!
B40: 11) Cash receipts: Charge | C40: =C12 -> #VALUE! | D40: =D12 -> #VALUE! | E40: =E12 -> #VALUE! | F40: =F12 -> #VALUE! | G40: =G12 -> #VALUE! | I40: =I12 -> #VALUE!
B41: 12) Credit memo: Late Charge | C41: =C14 -> #VALUE! | D41: =D14 -> #VALUE! | E41: =E14 -> #VALUE! | F41: =F14 -> #VALUE! | G41: =G14 -> #VALUE! | I41: =I14 -> #VALUE!
B42: Total | C42: =-C37-C38-C39-C40-C41 -> #VALUE! | D42: =-D37-D38-D39-D40-D41 -> #VALUE! | E42: =-E37-E38-E39-E40-E41 -> #VALUE! | F42: =-F37-F38-F39-F40-F41 -> #VALUE! | G42: =-G37-G38-G39-G40-G41 -> #VALUE! | I42: =-I37-I38-I39-I40-I41 -> #VALUE!
B43: CHECKSUM | C43: =C42-C19 -> #VALUE! | D43: =D42-D19 -> #VALUE! | E43: =E42-E19 -> #VALUE! | F43: =F42-F19 -> #VALUE! | G43: =G42-G19 -> #VALUE! | I43: =I42-I19 -> #VALUE!

Sheet Civil Debt Exceptions
B2: Migrated in Error
B5: Debt Transactions
B7: Transaction Type | C7: Contributions | D7: Costs | E7: Damages | F7: Revocation | G7: Statutory charge | I7: Total
B8: Debt invoices | C8: =SUM([3]FIXED_CASES_EXP!M:M) -> #REF! | D8: =SUM([3]FIXED_CASES_EXP!AE:AE) -> #REF! | E8: =SUM([3]FIXED_CASES_EXP!AW:AW) -> #REF! | F8: =SUM([3]FIXED_CASES_EXP!BO:BO) -> #REF! | G8: =SUM([3]FIXED_CASES_EXP!CG:CG) -> #REF! | I8: =SUM(C8:H8) -> #REF!
B9: Adjustment Charges | C9: =SUM([3]FIXED_CASES_EXP!O:O)*-1 -> #REF! | D9: =SUM([3]FIXED_CASES_EXP!AG:AG)*-1 -> #REF! | E9: =SUM([3]FIXED_CASES_EXP!AY:AY)*-1 -> #REF! | F9: =SUM([3]FIXED_CASES_EXP!BQ:BQ)*-1 -> #REF! | G9: =SUM([3]FIXED_CASES_EXP!CI:CI)*-1 -> #REF! | I9: =SUM(C9:H9) -> #REF!
B10: Adjustment: Other Increasing debt | C10: =SUM([3]FIXED_CASES_EXP!Q:Q)*-1 -> #REF! | D10: =SUM([3]FIXED_CASES_EXP!AI:AI)*-1 -> #REF! | E10: =SUM([3]FIXED_CASES_EXP!BA:BA)*-1 -> #REF! | F10: =SUM([3]FIXED_CASES_EXP!BS:BS)*-1 -> #REF! | G10: =SUM([3]FIXED_CASES_EXP!CN:CN)*-1 -> #REF! | I10: =SUM(C10:H10) -> #REF!
B11: Adjustments: Other Lowering debt | C11: =(SUM([3]FIXED_CASES_EXP!P:P)*-1)-C10 -> #REF! | D11: =(SUM([3]FIXED_CASES_EXP!AH:AH)*-1)-D10 -> #REF! | E11: =(SUM([3]FIXED_CASES_EXP!AZ:AZ)*-1)-E10 -> #REF! | F11: =(SUM([3]FIXED_CASES_EXP!BR:BR)*-1)-F10 -> #REF! | G11: =(SUM([3]FIXED_CASES_EXP!CJ:CJ)*-1)-G10 -> #REF! | I11: =SUM(C11:H11) -> #REF!
B12: Adjustments: Writeoff Charge | C12: =SUM([3]FIXED_CASES_EXP!W:W)*-1 -> #REF! | D12: =SUM([3]FIXED_CASES_EXP!AO:AO)*-1 -> #REF! | E12: =SUM([3]FIXED_CASES_EXP!BG:BG)*-1 -> #REF! | F12: =SUM([3]FIXED_CASES_EXP!BY:BY)*-1 -> #REF! | G12: =SUM([3]FIXED_CASES_EXP!CQ:CQ)*-1 -> #REF! | I12: =SUM(C12:H12) -> #REF!
B13: Adjustments: Writeoff Debt | C13: =SUM([3]FIXED_CASES_EXP!X:X)*-1 -> #REF! | D13: =SUM([3]FIXED_CASES_EXP!AP:AP)*-1 -> #REF! | E13: =SUM([3]FIXED_CASES_EXP!BH:BH)*-1 -> #REF! | F13: =SUM([3]FIXED_CASES_EXP!BZ:BZ)*-1 -> #REF! | G13: =SUM([3]FIXED_CASES_EXP!CR:CR)*-1 -> #REF! | I13: =SUM(C13:H13) -> #REF!
B14: Adjustments: Writedown Charge | C14: =SUM([3]FIXED_CASES_EXP!T:T)*-1 -> #REF! | D14: =SUM([3]FIXED_CASES_EXP!AL:AL)*-1 -> #REF! | E14: =SUM([3]FIXED_CASES_EXP!BD:BD)*-1 -> #REF! | F14: =SUM([3]FIXED_CASES_EXP!BV:BV)*-1 -> #REF! | G14: =SUM([3]FIXED_CASES_EXP!CL:CL)*-1 -> #REF! | I14: =SUM(C14:H14) -> #REF!
B15: Adjustments: Writedown Debt | C15: =SUM([3]FIXED_CASES_EXP!U:U)*-1 -> #REF! | D15: =SUM([3]FIXED_CASES_EXP!AM:AM)*-1 -> #REF! | E15: =SUM([3]FIXED_CASES_EXP!BE:BE)*-1 -> #REF! | F15: =SUM([3]FIXED_CASES_EXP!BW:BW)*-1 -> #REF! | G15: =SUM([3]FIXED_CASES_EXP!CM:CM)*-1 -> #REF! | I15: =SUM(C15:H15) -> #REF!
B16: Cash receipts: Charge | C16: =SUM([3]FIXED_CASES_EXP!Z:Z) -> #REF! | D16: =SUM([3]FIXED_CASES_EXP!AR:AR) -> #REF! | E16: =SUM([3]FIXED_CASES_EXP!BJ:BJ) -> #REF! | F16: =SUM([3]FIXED_CASES_EXP!CB:CB) -> #REF! | G16: =SUM([3]FIXED_CASES_EXP!CT:CT) -> #REF! | I16: =SUM(C16:H16) -> #REF!
B17: Cash receipts: Debt | C17: =SUM([3]FIXED_CASES_EXP!AA:AA) -> #REF! | D17: =SUM([3]FIXED_CASES_EXP!AS:AS) -> #REF! | E17: =SUM([3]FIXED_CASES_EXP!BK:BK) -> #REF! | F17: =SUM([3]FIXED_CASES_EXP!CC:CC) -> #REF! | G17: =SUM([3]FIXED_CASES_EXP!CU:CU) -> #REF! | I17: =SUM(C17:H17) -> #REF!
B18: Credit memo: Late Charge | C18: =SUM([3]FIXED_CASES_EXP!AC:AC) -> #REF! | D18: =SUM([3]FIXED_CASES_EXP!AU:AU) -> #REF! | E18: =SUM([3]FIXED_CASES_EXP!BM:BM) -> #REF! | F18: =SUM([3]FIXED_CASES_EXP!CE:CE) -> #REF! | G18: =SUM([3]FIXED_CASES_EXP!CW:CW) -> #REF! | I18: =SUM(C18:H18) -> #REF!
B19: Credit memo: Debt | C19: =SUM([3]FIXED_CASES_EXP!AD:AD) -> #REF! | D19: =SUM([3]FIXED_CASES_EXP!AV:AV) -> #REF! | E19: =SUM([3]FIXED_CASES_EXP!BN:BN) -> #REF! | F19: =SUM([3]FIXED_CASES_EXP!CF:CF) -> #REF! | G19: =SUM([3]FIXED_CASES_EXP!CX:CX) -> #REF! | I19: =SUM(C19:H19) -> #REF!
B21: Balance Principal | C21: =C8-C10-C11-C13-C15-C17-C19 -> #REF! | D21: =D8-D10-D11-D13-D15-D17-D19 -> #REF! | E21: =E8-E10-E11-E13-E15-E17-E19 -> #REF! | F21: =F8-F10-F11-F13-F15-F17-F19 -> #REF! | G21: =G8-G10-G11-G13-G15-G17-G19 -> #REF! | I21: =I8-I10-I11-I13-I15-I17-I19 -> #REF!
B23: Balance Charges | C23: =-C9-C12-C14-C16-C18 -> #REF! | D23: =-D9-D12-D14-D16-D18 -> #REF! | E23: =-E9-E12-E14-E16-E18 -> #REF! | F23: =-F9-F12-F14-F16-F18 -> #REF! | G23: =-G9-G12-G14-G16-G18 -> #REF! | I23: =-I9-I12-I14-I16-I18 -> #REF!
B25: Not Linked to Civil Case
B27: Transaction Type | C27: Contributions | D27: Costs | E27: Damages | F27: Revocation | G27: Statutory charge | I27: Total
B28: Debt invoices | C28: =SUMIF([4]CCMS_CIVIL_EXCEPTIONS_EXP!$L:$L,C$27,[4]CCMS_CIVIL_EXCEPTIONS_EXP!$O:$O) -> #VALUE! | D28: =SUMIF([4]CCMS_CIVIL_EXCEPTIONS_EXP!$L:$L,D$27,[4]CCMS_CIVIL_EXCEPTIONS_EXP!$O:$O) -> #VALUE! | E28: =SUMIF([4]CCMS_CIVIL_EXCEPTIONS_EXP!$L:$L,E$27,[4]CCMS_CIVIL_EXCEPTIONS_EXP!$O:$O) -> #VALUE! | F28: =SUMIF([4]CCMS_CIVIL_EXCEPTIONS_EXP!$L:$L,F$27,[4]CCMS_CIVIL_EXCEPTIONS_EXP!$O:$O) -> #VALUE! | G28: =SUMIF([4]CCMS_CIVIL_EXCEPTIONS_EXP!$L:$L,G$27,[4]CCMS_CIVIL_EXCEPTIONS_EXP!$O:$O) -> #VALUE! | I28: =SUM(C28:H28) -> #VALUE!
B29: Adjustment Charges | C29: =SUMIF([4]CCMS_CIVIL_EXCEPTIONS_EXP!$L:$L,C$27,[4]CCMS_CIVIL_EXCEPTIONS_EXP!$V:$V)*-1 -> #VALUE! | D29: =SUMIF([4]CCMS_CIVIL_EXCEPTIONS_EXP!$L:$L,D$27,[4]CCMS_CIVIL_EXCEPTIONS_EXP!$V:$V)*-1 -> #VALUE! | E29: =SUMIF([4]CCMS_CIVIL_EXCEPTIONS_EXP!$L:$L,E$27,[4]CCMS_CIVIL_EXCEPTIONS_EXP!$V:$V)*-1 -> #VALUE! | F29: =SUMIF([4]CCMS_CIVIL_EXCEPTIONS_EXP!$L:$L,F$27,[4]CCMS_CIVIL_EXCEPTIONS_EXP!$V:$V)*-1 -> #VALUE! | G29: =SUMIF([4]CCMS_CIVIL_EXCEPTIONS_EXP!$L:$L,G$27,[4]CCMS_CIVIL_EXCEPTIONS_EXP!$V:$V)*-1 -> #VALUE! | I29: =SUM(C29:H29) -> #VALUE!
B30: Adjustment: Other Increasing debt | C30: =SUMIF([4]CCMS_CIVIL_EXCEPTIONS_EXP!$L:$L,C$27,[4]CCMS_CIVIL_EXCEPTIONS_EXP!$T:$T)*-1 -> #VALUE! | D30: =SUMIF([4]CCMS_CIVIL_EXCEPTIONS_EXP!$L:$L,D$27,[4]CCMS_CIVIL_EXCEPTIONS_EXP!$T:$T)*-1 -> #VALUE! | E30: =SUMIF([4]CCMS_CIVIL_EXCEPTIONS_EXP!$L:$L,E$27,[4]CCMS_CIVIL_EXCEPTIONS_EXP!$T:$T)*-1 -> #VALUE! | F30: =SUMIF([4]CCMS_CIVIL_EXCEPTIONS_EXP!$L:$L,F$27,[4]CCMS_CIVIL_EXCEPTIONS_EXP!$T:$T)*-1 -> #VALUE! | G30: =SUMIF([4]CCMS_CIVIL_EXCEPTIONS_EXP!$L:$L,G$27,[4]CCMS_CIVIL_EXCEPTIONS_EXP!$T:$T)*-1 -> #VALUE! | I30: =SUM(C30:H30) -> #VALUE!
